Workbook

Sheet Rates
A1: Price List Data 17-07-21 | C1: Price june 2025 | D1: Previous Price
A3: 1 | B3: C.I. Gills | C3: 170 | D3: 170 | J3: Bought Out Items | P3: ENCON PURCHASE PRICE
A4: 2 | B4: C.I. Hub | C4: 375 | D4: 375 | K4: Price 2025 | M4: Previous price | P4: ITEM | S4: PRICE (Rs.) 2025 | U4: previous price
A5: 3 | B5: Coupling | C5: 350 | D5: 250 | J5: Casting Burner Parts | K5: 100 | L5: Per Kg | M5: 90 | P5: SEQUENCE CONTROLLER | T5: 10640 | U5: 5935.4
A6: 4 | B6: Hardware Bolt | C6: 150 | D6: 150 | J6: SS Assly 2A/3A | K6: 2500 | M6: 2300 | P6: VACUUM SWITCH | T6: 1200 | U6: 882
A7: 5 | B7: M.S. Angle 100,100 | C7: 71 | D7: 71 | J7: SS Assly 4A | K7: 2600 | M7: 2400 | P7: ARE-13 Burner Alone | T7: 30000 | U7: 21550
A8: 6 | B8: M.S. Angle 50*6 | C8: 71 | D8: 71 | J8: SS Assly 5A/6A | K8: 5000 | M8: 4500 | P8: ARE-22 Burner Alone | T8: 34400 | U8: 32623
A9: 7 | B9: M.S. Angle 65,50 | C9: 71 | D9: 71 | J9: SS Assly 7A | K9: 26000 | M9: 23000 | P9: ARE-35 Burner Alone | T9: 49000 | U9: =(27497/76.9)*79*1.4
A10: 8 | B10: M.S. Chanel | C10: 71 | D10: 71 | J10: Micro Valve 2A/3A | K10: 2300 | M10: 2075 | P10: ARE-50 Burner Alone | T10: 50000 | U10: 38000 | X10: 35000
A11: 9 | B11: M.S. Flat | C11: 71 | D11: 71 | J11: Micro Valve 4A | K11: 2300 | M11: 2075 | P11: ID FAN (ARE 13 & ARE 22) | T11: 14000 | U11: 10278.46
A12: 10 | B12: M.S. Plate 16mm* 5mm | C12: 72 | D12: 72 | J12: Micro Valve 5A/6A | K12: 2300 | M12: 2075 | P12: ID FAN (ARE 35) | T12: 15247 | U12: 10877.7
A13: 11 | B13: M.S. Plate 16mm*10mm | C13: 72 | D13: 72 | J13: Micro Valve 7A | K13: 2500 | M13: 2125 | P13: ID FAN (HEAVY DUTY) | T13: 25550 | U13: 19254
A14: 12 | B14: M.S. Plate 5mm | C14: 72 | D14: 72 | J14: FLEXIBLE HOSE-15NB*750MM (OIL ) | K14: 590 | M14: 590 | P14: ID FAN (TYPE O FAN) | T14: 45000 | U14: 41236 | V14: Check this fig
A15: 13 | B15: M.S. Plate 8mm | C15: 72 | D15: 72 | J15: FLEXIBLE HOSE-15NB*1000MM (OIL ) | K15: 750 | M15: 750 | P15: SOLENOID VALVE UNIT | T15: 8000 | U15: 4744 | X15: =3389*1.4
A16: 14 | B16: M.S. Round | C16: 72 | D16: 72 | J16: FLEXIBLE HOSE-20NB*1000MM (OIL ) | K16: 800 | M16: 800 | P16: ELECTRODE ASSEMBLY | T16: 2200 | U16: 560
A17: 15 | B17: M.S. Sheet 2mm | C17: 77 | D17: 77 | J17: FLEXIBLE HOSE-25NB*1000MM (AIR ) | K17: 1100 | M17: 1100 | P17: NOISE FILTER | T17: 400 | U17: 250
A18: 16 | B18: M.S. Sheet 3mm | C18: 77 | D18: 77 | J18: ADOPTER 15NB*20NB (OIL) | K18: 30 | M18: 30 | P18: INPUT SOCKET | T18: 1070 | U18: 280
A19: 17 | B19: M.S. Sheet 4mm | C19: 72 | D19: 72 | J19: ADOPTER 15NB*15NB (AIR) | K19: 30 | M19: 30
A20: 18 | B20: M.S. Sheet 5mm | C20: 72 | D20: 72
A21: 19 | B21: M.S. Sheet 8mm | C21: 72 | D21: 72 | J21: Butterfly Valve 2.5" | K21: 1500 | M21: 1500
A22: 20 | B22: M.S. Tube "B" Class 1.5 in | C22: 135 | D22: 135 | J22: Butterfly Valve 4" | K22: 1650 | M22: 1650
A23: 21 | B23: M.S. Tube "C" Class 1.5 in | C23: 135 | D23: 135 | J23: Butterfly Valve 6" | K23: 4500 | M23: 4500
A24: 22 | B24: M.S.Chanel | C24: 71 | D24: 71 | J24: ENCON-Y-STRAINER 20NB | K24: 450 | M24: 360
A25: 23 | B25: Plumber block with Bearing | C25: 13000 | D25: 11000 | J25: Whyteheat K | K25: 70 | M25: 50
A26: 24 | B26: Pulley with V belt | C26: 5000 | D26: 3000 | J26: Ball valve 25 NB | K26: 2500 | M26: 2500
A27: 25 | B27: S.S. Sheet 3mm | C27: 270 | D27: 270 | J27: ='Gas Burner'!B9 | K27: 1500 | M27: 1500
A28: 26 | B28: SS Pipe | J28: Ball valve 20 NB | K28: 1718 | M28: 1718
A29: 27 | B29: Ceramic Fiber | C29: 2000 | D29: 1450 | G29: Pipe Kg/Mtr | J29: Ball valve 32 NB | K29: 2929 | M29: 2929
A30: 28 | B30: SS Pipe 304 60 X 3mm | C30: 330 | D30: 330 | E30: =C30*G30 | G30: =PI()*60*60*7850*1/(4*1000*1000)-PI()*54*54*7850*1/(4*1000*1000) | J30: Ball valve 40 NB | K30: 5000 | M30: 5000
A31: 29 | B31: SS Pipe 304 76 X 3mm | C31: 330 | D31: 330 | E31: =C31*G31 | G31: =PI()*76*76*7850*1/(4*1000*1000)- PI()*70*70*7850*1/(4*1000*1000)
A32: 30 | B32: SS Pipe 304 100 X 3mm | C32: 330 | D32: 330 | E32: =C32*G32 | G32: =PI()*100*100*7850*1/(4*1000*1000)- PI()*94*94*7850*1/(4*1000*1000) | J32: DEMBLA CONTROL VALVES | N32: Make: DEMBLA
A33: 31 | B33: M.S. Elbow 60 OD | C33: 200 | D33: 200 | J33: Control Valve 050NB | K33: 172892 | N33: DEMBLA
A34: 32 | B34: M.S. Elbow 76 OD | C34: 300 | D34: 300 | J34: Control Valve 065NB | K34: 176475 | N34: DEMBLA
A35: 33 | B35: M.S. Elbow 100 OD | C35: 400 | D35: 400 | J35: Control Valve 080NB | K35: 183291 | N35: DEMBLA
A36: 34 | B36: SS Elbow 60 OD | C36: 600 | D36: 500 | J36: Control Valve 100NB | K36: 187598 | N36: DEMBLA
A37: 35 | B37: SS Elbow 76 OD | C37: 700 | D37: 600 | J37: Control Valve 125NB | K37: 201687 | N37: DEMBLA
A38: 36 | B38: SS Elbow 100 OD | C38: 1000 | D38: 900 | J38: Control Valve 150NB | K38: 205736 | N38: DEMBLA
J39: Control Valve 200NB | K39: 242404 | N39: DEMBLA
J40: Control Valve 250NB | K40: 305228 | N40: DEMBLA
J41: Control Valve 300NB | K41: 344828 | N41: DEMBLA
...

Sheet  Oil Burner
A1: BURNER PARTS-2A/3A | J1: BURNER PARTS-4A | S1: BURNER PARTS-5A/6A | AB1: BURNER PARTS-7A
A2: S.NO. | B2: PARTICULARS | C2: QTY | D2: UNIT | E2: RATE | F2: AMOUNT | G2: M/C COST | H2: TOTAL AMOUNT | J2: S.NO. | K2: PARTICULARS | L2: QTY | M2: UNIT | N2: RATE | O2: AMOUNT | P2: M/C COST | Q2: TOTAL AMOUNT | S2: S.NO. | T2: PARTICULARS | U2: QTY | V2: UNIT | W2: RATE | X2: AMOUNT | Y2: M/C COST | Z2: TOTAL AMOUNT | AB2: S.NO. | AC2: PARTICULARS | AD2: QTY | AE2: UNIT | AF2: RATE | AG2: AMOUNT | AH2: M/C COST | AI2: TOTAL AMOUNT
A4: 1 | B4: ENCON-2A/3A BASE PLATE | C4: 10.5 | D4: Kgs | E4: =Rates!$K$5 | F4: =C4*E4 | G4: 500 | H4: =F4+G4 | J4: 1 | K4: ENCON-4A BASE PLATE | L4: 13.5 | M4: Kgs | N4: =Rates!$K$5 | O4: =L4*N4 | P4: 500 | Q4: =O4+P4 | S4: 1 | T4: ENCON-5A/6A BASE PLATE | U4: 24 | V4: Kgs | W4: =Rates!$K$5 | X4: =U4*W4 | Y4: 550 | Z4: =X4+Y4 | AB4: 1 | AC4: ENCON-7A AIR TUBE-205(dia)*180(I.D)*375(Lenth) | AD4: 22.24 | AE4: Kgs | AF4: 80 | AG4: =AD4*AF4 | AI4: =AG4+AH4
A5: 2 | B5: ENCON-2A/3AAIR TUBE | C5: 3.9 | D5: Kgs | E5: =Rates!$K$5 | F5: =C5*E5 | G5: 500 | H5: =F5+G5 | J5: 2 | K5: ENCON-4A AIR TUBE | L5: 6.8 | M5: Kgs | N5: =Rates!$K$5 | O5: =L5*N5 | P5: 500 | Q5: =O5+P5 | S5: 2 | T5: ENCON-5A/6AAIR TUBE | U5: 16.8 | V5: Kgs | W5: =Rates!$K$5 | X5: =U5*W5 | Y5: 500 | Z5: =X5+Y5 | AB5: 2 | AC5: M.S.FLANGE-300 (dia)* 195 (I.D)*12MM Thick | AD5: 7.68 | AE5: Kgs | AF5: 72 | AG5: =AD5*AF5 | AH5: 1500 | AI5: =AG5+AH5
A6: 3 | B6: ENCON-2A/3AS.G.HOLDER | C6: 2.6 | D6: Kgs | E6: =Rates!$K$5 | F6: =C6*E6 | G6: 200 | H6: =F6+G6 | J6: 3 | K6: ENCON-4AS.G.HOLDER | L6: 4.3 | M6: Kgs | N6: =Rates!$K$5 | O6: =L6*N6 | P6: 200 | Q6: =O6+P6 | S6: 3 | T6: ENCON-5A/6AS.G.HOLDER | U6: 8.4 | V6: Kgs | W6: =Rates!$K$5 | X6: =U6*W6 | Y6: 300 | Z6: =X6+Y6 | AB6: 3 | AC6: M.S. PIPE-100NB*125MM | AD6: 1 | AE6: NO | AF6: =Rates!C22 | AG6: =AD6*AF6 | AI6: =AG6+AH6
A7: 4 | B7: ENCON-2A/3A AIR ADJUSTER | C7: 3 | D7: Kgs | E7: =Rates!$K$5 | F7: =C7*E7 | G7: 100 | H7: =F7+G7 | J7: 4 | K7: ENCON-4A AIR ADJUSTER | L7: 3.8 | M7: Kgs | N7: =Rates!$K$5 | O7: =L7*N7 | P7: 100 | Q7: =O7+P7 | S7: 4 | T7: ENCON-5A/6A AIR ADJUSTER | U7: 4.7 | V7: Kgs | W7: =Rates!$K$5 | X7: =U7*W7 | Y7: 100 | Z7: =X7+Y7 | AB7: 4 | AC7: ENCON-7A AIR MIXER-86(dia)*72(I.D)*385(Lenth) | AD7: 5.24 | AE7: Kgs | AF7: 80 | AG7: =AD7*AF7 | AI7: =AG7+AH7
A8: 5 | B8: ENCON-2A/3A S.S.ASSY. | C8: 1 | D8: SET | E8: =Rates!K6 | F8: =C8*E8 | H8: =F8+G8 | J8: 5 | K8: ENCON-4A S.S.ASSY. | L8: 1 | M8: SET | N8: =Rates!K7 | O8: =L8*N8 | Q8: =O8+P8 | S8: 5 | T8: ENCON-5A/6A S.S.ASSY. | U8: 1 | V8: SET | W8: =Rates!K8 | X8: =U8*W8 | Z8: =X8+Y8 | AB8: 5 | AC8: M.S.TIKKY-300(dia)*80(I.D)*40MM Thick | AD8: 20.6 | AE8: Kgs | AF8: 72 | AG8: =AD8*AF8 | AI8: =AG8+AH8
A9: 6 | B9: ENCON-2A/3A BUTTERFLY VALVE-2.5 (INCH ) | C9: 1 | D9: NO | E9: =Rates!K21 | F9: =C9*E9 | H9: =F9+G9 | J9: 6 | K9: ENCON-4A BUTTERFLY VALVE-4 (INCH ) | L9: 1 | M9: NO | N9: =Rates!K22 | O9: =L9*N9 | Q9: =O9+P9 | S9: 6 | T9: ENCON-5A/6A BUTTERFLY VALVE-4 (INCH ) | U9: 1 | V9: NO | W9: =Rates!K22 | X9: =U9*W9 | Z9: =X9+Y9 | AB9: 6 | AC9: ENCON-7A AIR TUBE-88(dia)*72(I.D)*135MM(Lenth) | AD9: 2.12 | AE9: Kgs | AF9: 80 | AG9: =AD9*AF9 | AI9: =AG9+AH9
A10: 7 | B10: ENCON-2A/3A Y-STRAINER 20NB | C10: 1 | D10: NO | E10: =Rates!K24 | F10: =C10*E10 | H10: =F10+G10 | J10: 7 | K10: ENCON-4A Y-STRAINER 20NB | L10: 1 | M10: NO | N10: =Rates!K24 | O10: =L10*N10 | Q10: =O10+P10 | S10: 7 | T10: ENCON-5A/6AY-STRAINER 20NB | U10: 1 | V10: NO | W10: =N10 | X10: =U10*W10 | Z10: =X10+Y10 | AB10: 7 | AC10: M.S.TIKKY- 175(dia)*80(I.D)*16MM Thick | AD10: 2.38 | AE10: Kgs | AF10: 72 | AG10: =AD10*AF10 | AI10: =AG10+AH10
A11: 8 | B11: FLEXIBLE HOSE-15NB*750MM (OIL ) | C11: 1 | D11: NO | E11: =Rates!K14 | F11: =C11*E11 | H11: =F11+G11 | J11: 8 | K11: FLEXIBLE HOSE-15NB*750MM (OIL ) | L11: 1 | M11: NO | N11: =E11 | O11: =L11*N11 | Q11: =O11+P11 | S11: 8 | T11: FLEXIBLE HOSE-15NB*1000MM(OIL ) | U11: 1 | V11: NO | W11: =Rates!K15 | X11: =U11*W11 | Z11: =X11+Y11 | AB11: 8 | AC11: M.S. TIKKY-90(dia)*40(I.D)*40MM Thick | AD11: 1.6 | AE11: Kgs | AF11: 72 | AG11: =AD11*AF11 | AI11: =AG11+AH11
A12: 9 | B12: FLEXIBLE HOSE-15NB*750MM (AIR ) | C12: 1 | D12: NO | E12: =E11 | F12: =C12*E12 | H12: =F12+G12 | J12: 9 | K12: FLEXIBLE HOSE-15NB*750MM (AIR ) | L12: 1 | M12: NO | N12: =N11 | O12: =L12*N12 | Q12: =O12+P12 | S12: 9 | T12: FLEXIBLE HOSE-20NB*1000MM (AIR ) | U12: 1 | V12: NO | W12: =Rates!K16 | X12: =U12*W12 | Z12: =X12+Y12 | AB12: 9 | AC12: ENCON-7A SPACER-80(dia)*40(I.D)*35MM(Lenth) | AD12: 1 | AE12: Kgs | AF12: 72 | AG12: =AD12*AF12 | AI12: =AG12+AH12
A13: 10 | B13: GUN METAL MICRO VALVE -2A/3A | C13: 1 | D13: NO | E13: =Rates!K10 | F13: 2500 | H13: =F13+G13 | J13: 10 | K13: GUN METAL MICRO VALVE -4A | L13: 1 | M13: NO | N13: =Rates!K11 | O13: =L13*N13 | Q13: =O13+P13 | S13: 10 | T13: GUN METAL MICRO VALVE -5A/6A | U13: 1 | V13: NO | W13: =Rates!K12 | X13: =U13*W13 | Z13: =X13+Y13 | AB13: 10 | AC13: ENCON-7A S.S ASSY. | AD13: 1 | AE13: Set | AF13: =Rates!K9 | AG13: =AD13*AF13 | AI13: =AG13+AH13
A14: 11 | B14: ADOPTER 15NB*20NB (OIL) | C14: 1 | D14: NO | E14: 30 | F14: =C14*E14 | H14: =F14+G14 | J14: 11 | K14: ADOPTER 15NB*20NB (OIL) | L14: 1 | M14: NO | N14: 30 | O14: =L14*N14 | Q14: =O14+P14 | S14: 11 | T14: ADOPTER 15NB*20NB (OIL) | U14: 1 | V14: NO | W14: 30 | X14: =U14*W14 | Z14: =X14+Y14 | AB14: 11 | AC14: ENCON-7A MICRO VALVE | AD14: 1 | AE14: NO | AF14: =Rates!K13 | AG14: =AD14*AF14 | AI14: =AG14+AH14
A15: 12 | B15: ADOPTER 15NB*15NB (AIR) | C15: 2 | D15: Nos | E15: 30 | F15: =C15*E15 | H15: =F15+G15 | J15: 12 | K15: ADOPTER 20NB*20NB (AIR) | L15: 2 | M15: Nos | N15: 30 | O15: =L15*N15 | Q15: =O15+P15 | S15: 12 | T15: ADOPTER 20NB*20NB (AIR) | U15: 2 | V15: Nos | W15: 30 | X15: =U15*W15 | Z15: =X15+Y15 | AB15: 12 | AC15: FLEXIBLE HOSE-20NB*1000MM (OIL ) | AD15: 1 | AE15: set | AF15: =Rates!K16 | AG15: =AD15*AF15 | AI15: =AG15+AH15
A16: 13 | B16: ENCON-2A/3ABURNER PLATE | C16: 30.1 | D16: Kgs | E16: =Rates!$K$5 | F16: =C16*E16 | H16: =F16+G16 | J16: 13 | K16: ENCON-4ABURNER PLATE | L16: 41.4 | M16: Kgs | N16: =Rates!$K$5 | O16: =L16*N16 | Q16: =O16+P16 | S16: 13 | T16: ENCON-5A/6ABURNER PLATE | U16: 50 | V16: Kgs | W16: =Rates!$K$5 | X16: =U16*W16 | Z16: =X16+Y16 | AB16: 13 | AC16: FLEXIBLE HOSE-25NB*1000MM (AIR ) | AD16: 1 | AE16: No | AF16: =Rates!K17 | AG16: =AD16*AF16 | AI16: =AG16+AH16
A17: 14 | B17: ENCON-2A/3A BURNER BLOCK | C17: 50 | D17: Kgs | E17: =Rates!K25 | F17: =C17*E17 | G17: 100 | H17: =F17+G17 | J17: 14 | K17: ENCON-4A BURNER BLOCK | L17: 65 | M17: Kgs | N17: =E17 | O17: =L17*N17 | P17: 100 | Q17: =O17+P17 | S17: 14 | T17: ENCON-5A/6A BURNER BLOCK | U17: 110 | V17: Kgs | W17: =N17 | X17: =U17*W17 | Y17: 250 | Z17: =X17+Y17 | AB17: 14 | AC17: Butterfly valve | AD17: 1 | AE17: No | AF17: =Rates!K23 | AG17: =AD17*AF17 | AI17: =AG17+AH17
A18: 15 | B18: PAINT PRIMER,BOLT | H18: 250 | K18: labour charge | Q18: 500 | T18: labour charge | Z18: 500 | AB18: 15 | AC18: Y-STRAINER 25NB | AD18: 1 | AE18: No | AF18: =Rates!K24 | AG18: =AD18*AF18 | AI18: =AG18+AH18
B19: labour charge | H19: 400 | K19: PAINT PRIMER,BOLT | O19: 300 | Q19: 300 | S19: 15 | T19: PAINT PRIMER,BOLT | X19: 350 | Z19: 400 | AB19: 16 | AC19: ENCON-7A BURNER BLOCK | AD19: 150 | AE19: Kgs | AF19: =W17 | AG19: =AD19*AF19 | AH19: 300 | AI19: =AG19+AH19
G20: TOTAL | H20: =SUM(H4:H19) | N20: TOTAL | Q20: =SUM(Q4:Q19) | W20: TOTAL | Z20: =SUM(Z4:Z19) | AB20: 17 | AC20: Burner plate | AD20: 50 | AE20: Kgs | AF20: =Rates!K5 | AG20: =AD20*AF20 | AI20: =AG20+AH20
J21: 1 | K21: H.V. BURNER-4A | L21: 1 | M21: NO | Q21: 17311 | S21: 1 | T21: H.V. BURNER -5A/6A | U21: 1 | V21: NO | Z21: 25968 | AB21: 18 | AC21: M.S.PIPE-50NB*100MM | AD21: 1 | AE21: NO | AF21: 80 | AG21: =AD21*AF21 | AI21: =AG21+AH21
A22: 1 | B22: H.V. BURNER-2A/3A | C22: 1 | D22: NO | H22: 14800 | AB22: 19 | AC22: Labour charge | AI22: 5000
AC23: PAINT PRIMER,BOLT | AG23: 500 | AI23: =AG23+AH23
AF24: TOTAL | AI24: =SUM(AI4:AI23)
B37: Burner Size | C37: S.G. Assembly | D37: S.G. Holder | E37: Inner Tube | F37: Outer Tube | G37: Lock Nut | H37: Check Nut | I37: Swirler | J37: Base Plate | K37: Air Tube | L37: Air Adjuster
B38: ENCON-2A | C38: 2282 | D38: 382 | E38: 850 | F38: 600 | G38: 200 | H38: 125 | I38: 125 | J38: 1235 | K38: 573 | L38: 310
B39: ENCON-3A | C39: 2282 | D39: 382 | E39: 850 | F39: 600 | G39: 200 | H39: 125 | I39: 125 | J39: 1235 | K39: 573 | L39: 310
B40: ENCON-4A | C40: 2551 | D40: 501 | E40: 950 | F40: 650 | G40: 200 | H40: 125 | I40: 125 | J40: 1445 | K40: 776 | L40: 366
B41: ENCON-5A | C41: 4788 | D41: 888 | E41: 2100 | F41: 1200 | G41: 250 | H41: 150 | I41: 200 | J41: 2230 | K41: 1576 | L41: 429
B42: ENCON-6A | C42: 4388 | D42: 888 | E42: 2100 | F42: 1200 | G42: 250 | H42: 150 | I42: 200 | J42: 2230 | K42: 1576 | L42: 429
B43: ENCON-7A | C43: 17000 | E43: 10800 | F43: 5800 | H43: 250 | I43: 150 | J43: 3500

Sheet HV  Oil Burner
A1: HV BURNER PARTS-2A/3A | J1: HV BURNER PARTS-4A | S1: HV BURNER PARTS-5A/6A | AB1: HV BURNER PARTS-7A
A2: S.NO. | B2: PARTICULARS | C2: QTY | D2: UNIT | E2: RATE | F2: AMOUNT | G2: M/C COST | H2: TOTAL AMOUNT | J2: S.NO. | K2: PARTICULARS | L2: QTY | M2: UNIT | N2: RATE | O2: AMOUNT | P2: M/C COST | Q2: TOTAL AMOUNT | S2: S.NO. | T2: PARTICULARS | U2: QTY | V2: UNIT | W2: RATE | X2: AMOUNT | Y2: M/C COST | Z2: TOTAL AMOUNT | AB2: S.NO. | AC2: PARTICULARS | AD2: QTY | AE2: UNIT | AF2: RATE | AG2: AMOUNT | AH2: M/C COST | AI2: TOTAL AMOUNT
A3: 1 | B3: H.V. BURNER-2A/3A | H3: =SUM(' Oil Burner'!H5:H6,' Oil Burner'!H8) | J3: 1 | K3: H.V. BURNER-4A | Q3: =SUM(' Oil Burner'!Q5:Q6,' Oil Burner'!Q8) | S3: 1 | T3: H.V. BURNER-5A/6A | Z3: =SUM(' Oil Burner'!Z5,' Oil Burner'!Z6,' Oil Burner'!Z8) | AB3: 1 | AC3: ENCON-7A AIR TUBE-205(dia)*180(I.D)*375(Lenth) | AD3: 22.24 | AE3: Kgs | AF3: =' Oil Burner'!AF4 | AG3: =AD3*AF3 | AI3: =AG3+AH3
A4: 2 | B4: H.V. BURNER block -2A/3A | H4: 9102 | J4: 2 | K4: H.V. BURNER block -4A | Q4: 11454 | S4: 2 | T4: H.V. BURNER block -5A/6A | Z4: 16654 | AB4: 2 | AC4: M.S.FLANGE-300 (dia)* 195 (I.D)*12MM Thick | AD4: 7.68 | AE4: Kgs | AF4: =' Oil Burner'!AF5 | AG4: =AD4*AF4 | AH4: 1500 | AI4: =AG4+AH4
A5: 3 | B5: ENCON-2A/3A BUTTERFLY VALVE-2.5 (INCH ) | C5: 1 | D5: NO | E5: =Rates!K21 | F5: =C5*E5 | H5: =F5+G5 | J5: 3 | K5: ENCON-4A BUTTERFLY VALVE-4 (INCH ) | L5: 1 | M5: NO | N5: =Rates!K22 | O5: =L5*N5 | Q5: =O5+P5 | S5: 3 | T5: ENCON-5A/6A BUTTERFLY VALVE-4 (INCH ) | U5: 1 | V5: NO | W5: =Rates!K22 | X5: =U5*W5 | Z5: =X5+Y5 | AB5: 3 | AC5: M.S. PIPE-100NB*125MM | AD5: 1 | AE5: NO | AF5: =' Oil Burner'!AF6 | AG5: =AD5*AF5 | AI5: =AG5+AH5
A6: 4 | B6: ENCON-2A/3A Y-STRAINER 20NB | C6: 1 | D6: NO | E6: =Rates!K24 | F6: =C6*E6 | H6: =F6+G6 | J6: 4 | K6: ENCON-4A Y-STRAINER 20NB | L6: 1 | M6: NO | N6: =E6 | O6: =L6*N6 | Q6: =O6+P6 | S6: 4 | T6: ENCON-5A/6AY-STRAINER 20NB | U6: 1 | V6: NO | W6: =Rates!K24 | X6: =U6*W6 | Z6: =X6+Y6 | AB6: 4 | AC6: ENCON-7A AIR MIXER-86(dia)*72(I.D)*385(Lenth) | AD6: 5.24 | AE6: Kgs | AF6: =' Oil Burner'!AF7 | AG6: =AD6*AF6 | AI6: =AG6+AH6
A7: 5 | B7: FLEXIBLE HOSE-15NB*750MM (OIL ) | C7: 2 | D7: NO | E7: =Rates!K14 | F7: =C7*E7 | H7: =F7+G7 | J7: 5 | K7: FLEXIBLE HOSE-15NB*750MM (OIL ) | L7: 2 | M7: NO | N7: =E7 | O7: =L7*N7 | Q7: =O7+P7 | S7: 5 | T7: FLEXIBLE HOSE-15NB*1000MM(OIL ) | U7: 1 | V7: NO | W7: =Rates!K15 | X7: =U7*W7 | Z7: =X7+Y7 | AB7: 5 | AC7: M.S.TIKKY-300(dia)*80(I.D)*40MM Thick | AD7: 20.6 | AE7: Kgs | AF7: =' Oil Burner'!AF8 | AG7: =AD7*AF7 | AI7: =AG7+AH7
A8: 6 | B8: FLEXIBLE HOSE-15NB*750MM (AIR ) | C8: 2 | D8: NO | E8: =E7 | F8: =C8*E8 | H8: =F8+G8 | J8: 6 | K8: FLEXIBLE HOSE-15NB*750MM (AIR ) | L8: 2 | M8: NO | N8: =E8 | O8: =L8*N8 | Q8: =O8+P8 | S8: 6 | T8: FLEXIBLE HOSE-20NB*1000MM (AIR ) | U8: 1 | V8: NO | W8: =Rates!K16 | X8: =U8*W8 | Z8: =X8+Y8 | AB8: 6 | AC8: ENCON-7A AIR TUBE-88(dia)*72(I.D)*135MM(Lenth) | AD8: 2.12 | AE8: Kgs | AF8: =' Oil Burner'!AF9 | AG8: =AD8*AF8 | AI8: =AG8+AH8
A9: 7 | B9: GUN METAL MICRO VALVE -2A/3A | C9: 1 | D9: NO | E9: =Rates!K10 | F9: =C9*E9 | H9: =F9+G9 | J9: 7 | K9: GUN METAL MICRO VALVE -4A | L9: 1 | M9: NO | N9: =Rates!K11 | O9: =L9*N9 | Q9: =O9+P9 | S9: 7 | T9: FLEXIBLE HOSE-15NB*750MM with adopter | U9: 2 | V9: set | W9: =Rates!K14 | X9: =U9*W9 | Z9: =X9+Y9 | AB9: 7 | AC9: M.S.TIKKY- 175(dia)*80(I.D)*16MM Thick | AD9: 2.38 | AE9: Kgs | AF9: =' Oil Burner'!AF10 | AG9: =AD9*AF9 | AI9: =AG9+AH9
A10: 8 | B10: ADOPTER 15NB*20NB (OIL) | C10: 3 | D10: NO | E10: 30 | F10: =C10*E10 | H10: =F10+G10 | J10: 8 | K10: ADOPTER 15NB*20NB (OIL) | L10: 3 | M10: NO | N10: 30 | O10: =L10*N10 | Q10: =O10+P10 | S10: 8 | T10: GUN METAL MICRO VALVE -5A/6A | U10: 1 | V10: NO | W10: =Rates!K12 | X10: =U10*W10 | Z10: =X10+Y10 | AB10: 8 | AC10: M.S. TIKKY-90(dia)*40(I.D)*40MM Thick | AD10: 1.6 | AE10: Kgs | AF10: =' Oil Burner'!AF11 | AG10: =AD10*AF10 | AI10: =AG10+AH10
A11: 9 | B11: ADOPTER 15NB*15NB (AIR) | C11: 4 | D11: Nos | E11: 30 | F11: =C11*E11 | H11: =F11+G11 | J11: 9 | K11: ADOPTER 20NB*20NB (AIR) | L11: 4 | M11: Nos | N11: 30 | O11: =L11*N11 | Q11: =O11+P11 | S11: 9 | T11: ADOPTER 15NB*20NB (OIL) | U11: 1 | V11: NO | W11: 30 | X11: =U11*W11 | Z11: =X11+Y11 | AB11: 9 | AC11: ENCON-7A SPACER-80(dia)*40(I.D)*35MM(Lenth) | AD11: 1 | AE11: Kgs | AF11: =' Oil Burner'!AF12 | AG11: =AD11*AF11 | AI11: =AG11+AH11
A12: 10 | B12: Labour charge | H12: 2100 | J12: 10 | K12: labour charge | Q12: 2400 | S12: 10 | T12: ADOPTER 20NB*20NB (AIR) | U12: 2 | V12: Nos | W12: 30 | X12: =U12*W12 | Z12: =X12+Y12 | AB12: 10 | AC12: ENCON-7A S.S ASSY. | AD12: 1 | AE12: Set | AF12: =' Oil Burner'!AF13 | AG12: =AD12*AF12 | AI12: =AG12+AH12
A13: 11 | B13: PAINT PRIMER,BOLT | H13: 400 | J13: 11 | K13: PAINT PRIMER,BOLT | O13: 300 | Q13: 400 | S13: 11 | T13: labour charge | Z13: 2900 | AB13: 11 | AC13: ENCON-7A MICRO VALVE | AD13: 1 | AE13: NO | AF13: =' Oil Burner'!AF14 | AG13: =AD13*AF13 | AI13: =AG13+AH13
G14: Total | H14: =SUM(H3:H13) | N14: TOTAL | Q14: =SUM(Q3:Q13) | S14: 12 | T14: PAINT PRIMER,BOLT | X14: 350 | Z14: 400 | AB14: 12 | AC14: FLEXIBLE HOSE-20NB*1000MM (OIL ) | AD14: 3 | AE14: set | AF14: =' Oil Burner'!AF15 | AG14: =AD14*AF14 | AI14: =AG14+AH14
W15: TOTAL | Z15: =SUM(Z3:Z14) | AB15: 13 | AC15: FLEXIBLE HOSE-25NB*1000MM (AIR ) | AD15: 1 | AE15: No | AF15: =' Oil Burner'!AF16 | AG15: =AD15*AF15 | AI15: =AG15+AH15
AB16: 14 | AC16: Butterfly valve | AD16: 1 | AE16: No | AF16: =' Oil Burner'!AF17 | AG16: =AD16*AF16 | AI16: =AG16+AH16
AB17: 15 | AC17: Y-STRAINER 25NB | AD17: 1 | AE17: No | AF17: =' Oil Burner'!AF18 | AG17: =AD17*AF17 | AI17: =AG17+AH17
AB18: 16 | AC18: ENCON-7A BURNER BLOCK | AD18: 1 | AE18: No | AF18: =' Oil Burner'!AF19 | AI18: 31048
AB19: 17 | AC19: M.S.PIPE-50NB*100MM | AD19: 1 | AE19: NO | AF19: =' Oil Burner'!AF21 | AG19: =AD19*AF19 | AI19: =AG19+AH19
AB20: 18 | AC20: Labour charge | AI20: 5000
AB21: 19 | AC21: PAINT PRIMER,BOLT | AG21: 400 | AI21: 500
AF22: TOTAL | AI22: =SUM(AI3:AI21)

Sheet Recuperator
A1: Recuperator F | M1: Recuperator HT
A2: Model | B2: MS Tube "C" Class (mtr) | C2: CI Gills (Nos) | D2: M.S. Angle 65,50 (Kg) | E2: M.S. Angle 100,100 (Kg) | F2: M.S Plate 16mm* 5mm | G2: Hardware Bolt (KG) | H2: M.S.Chanel (Kg) | I2: Toal Cost | M2: Model | N2: M.S. Plate 16mm*10mm | O2: M.S. Plate 5mm | P2: M.S. Angle 50*6 | Q2: S.S Sheet | R2: Total Cost
A3: 10 F | B3: 38 | D3: 269 | E3: 103 | F3: 200 | G3: 18 | H3: 98 | I3: =K12 | M3: 1 HT | N3: 29 | O3: 129 | P3: 9 | Q3: 62 | R3: =T12
A4: 20 F | B4: 64 | D4: 270 | E4: 56 | F4: 450 | G4: 20 | I4: =K13 | M4: 2 HT | N4: 32 | O4: 150 | P4: 9 | Q4: 86 | R4: =T13
A5: 30 F | B5: 128 | D5: 427 | E5: 279 | F5: 795 | G5: 30 | I5: =K14 | M5: 5 HT | N5: 53 | O5: 311 | P5: 13.5 | Q5: 223 | R5: =T14
A6: 40 F | B6: 146 | D6: 392 | E6: 305 | F6: 795 | G6: 40 | I6: =K15 | M6: 10 HT | N6: 93 | O6: 571 | P6: 22 | Q6: 435 | R6: =T15
A7: 50 F | B7: 182 | D7: 431 | E7: 312 | F7: 960 | G7: 40 | I7: =K16
A8: 100 F | B8: 354 | D8: 456 | E8: 381 | F8: 170 | G8: 35 | I8: =K17
A11: Model | B11: MS Tube "C" Class (mtr) | C11: CI Gills (Nos) | D11: M.S. Angle 65,50 (Kg) | E11: M.S. Angle 100,100 (Kg) | F11: M.S Plate 16mm* 5mm | G11: Hardware Bolt (KG) | H11: M.S.Chanel (Kg) | I11: Toal Cost | J11: 0.3 | K11: 0.8 | M11: Model | N11: M.S. Plate 16mm*10mm | O11: M.S. Plate 5mm | P11: M.S. Angle 50*6 | Q11: S.S Sheet | R11: cost | S11: 0.3 | T11: 0.8
A12: 10 F | B12: =(B3/0.3*Rates!$C$23) | C12: 0 | D12: =D3*Rates!$C$9 | E12: =E3*Rates!$C$7 | F12: =F3*Rates!$C$12 | G12: =G3*Rates!$C$6 | H12: =H3*Rates!C10 | I12: =SUM(B12:G12) | J12: =I12*1.3 | K12: =J12*1.8 | M12: 1 HT | N12: =N3*Rates!$C$13 | O12: =O3*Rates!$C$14 | P12: =P3*Rates!$C$8 | Q12: =Q3*Rates!$C$27 | R12: =SUM(N12:Q12) | S12: =R12*1.3 | T12: =S12*1.8
A13: 20 F | B13: =(B4/0.3*Rates!$C$23) | C13: 0 | D13: =D4*Rates!$C$9 | E13: =E4*Rates!$C$7 | F13: =F4*Rates!$C$12 | G13: =G4*Rates!$C$6 | I13: =SUM(B13:G13) | J13: =I13*1.3 | K13: =J13*1.8 | M13: 2 HT | N13: =N4*Rates!$C$13 | O13: =O4*Rates!$C$14 | P13: =P4*Rates!$C$8 | Q13: =Q4*Rates!$C$27 | R13: =SUM(N13:Q13) | S13: =R13*1.3 | T13: =S13*1.8
A14: 30 F | B14: =(B5/0.3*Rates!$C$23) | C14: 0 | D14: =D5*Rates!$C$9 | E14: =E5*Rates!$C$7 | F14: =F5*Rates!$C$12 | G14: =G5*Rates!$C$6 | I14: =SUM(B14:G14) | J14: =I14*1.3 | K14: =J14*1.8 | M14: 5 HT | N14: =N5*Rates!$C$13 | O14: =O5*Rates!$C$14 | P14: =P5*Rates!$C$8 | Q14: =Q5*Rates!$C$27 | R14: =SUM(N14:Q14) | S14: =R14*1.3 | T14: =S14*1.8
A15: 40 F | B15: =(B6/0.3*Rates!$C$23) | C15: 0 | D15: =D6*Rates!$C$9 | E15: =E6*Rates!$C$7 | F15: =F6*Rates!$C$12 | G15: =G6*Rates!$C$6 | I15: =SUM(B15:G15) | J15: =I15*1.3 | K15: =J15*1.8 | M15: 10 HT | N15: =N6*Rates!$C$13 | O15: =O6*Rates!$C$14 | P15: =P6*Rates!$C$8 | Q15: =Q6*Rates!$C$27 | R15: =SUM(N15:Q15) | S15: =R15*1.3 | T15: =S15*1.8
A16: 50 F | B16: =(B7/0.3*Rates!$C$23) | C16: 0 | D16: =D7*Rates!$C$9 | E16: =E7*Rates!$C$7 | F16: =F7*Rates!$C$12 | G16: =G7*Rates!$C$6 | I16: =SUM(B16:G16) | J16: =I16*1.3 | K16: =J16*1.8
A17: 100 F | B17: =(B8/0.3*Rates!$C$23) | C17: 0 | D17: =D8*Rates!$C$9 | E17: =E8*Rates!$C$7 | F17: =F8*Rates!$C$12 | G17: =G8*Rates!$C$6 | I17: =SUM(B17:G17) | J17: =I17*1.3 | K17: =J17*1.8
A19: Recuperator FS
A20: Model | B20: MS Tube "C" Class (mtr) | C20: MS Tube "B" Class (mtr) | D20: CI Gills (Nos) | E20: M.S. Angle 65,50 (Kg) | F20: M.S. Angle 100,100 (Kg) | G20: M.S Plate 16mm* 5mm | H20: Hardware Bolt (kg) | I20: M.S.Chanel (kg) | J20: Total Cost
A21: 10 FS | B21: 25 | C21: 25 | E21: 269 | F21: 103 | G21: 245 | H21: 18 | I21: 98 | J21: =L31
A22: 20 FS | B22: 52 | C22: 52 | E22: 344 | F22: 227 | G22: 575 | H22: 23 | J22: =L32
A23: 30 FS | B23: 91 | C23: 91 | E23: 390 | F23: 280 | G23: 798 | H23: 30 | J23: =L33
A24: 40 FS | B24: 124 | C24: 124 | E24: 395 | F24: 305 | G24: 825 | H24: 35 | J24: =L34
A25: 50 FS | B25: 158 | C25: 158 | E25: 510 | F25: 312 | G25: 950 | H25: 37 | J25: =L35
A26: 70 FS | B26: 261 | C26: 261 | E26: 516 | F26: 352 | G26: 1015 | H26: 30 | J26: =L36
A27: 100 FS | B27: 315 | C27: 315 | E27: 456 | F27: 381 | G27: 1190 | H27: 35 | J27: =L37
A30: Model | B30: MS Tube "C" Class (mtr) | C30: MS Tube "B" Class (mtr) | D30: CI Gills (Nos) | E30: M.S. Angle 65,50 (Kg) | F30: M.S. Angle 100,100 (Kg) | G30: M.S Plate 16mm* 5mm | H30: Hardware Bolt (kg) | I30: M.S.Chanel (kg) | K30: 0.3 | L30: 0.8
A31: 10 FS | B31: =B21*Rates!$C$23*4.27 | C31: =C21*Rates!$C$22*4.27 | E31: =E21*Rates!$C$9 | F31: =F21*Rates!$C$7 | G31: =G21*Rates!$C$12 | H31: =H21*Rates!$C$6 | I31: =I21*Rates!$C$10 | J31: =SUM(B31:I31) | K31: =J31*1.3 | L31: =K31*1.8
A32: 20 FS | B32: =B22*Rates!$C$23*4.27 | C32: =C22*Rates!$C$22*4.27 | E32: =E22*Rates!$C$9 | F32: =F22*Rates!$C$7 | G32: =G22*Rates!$C$12 | H32: =H22*Rates!$C$6 | I32: =I22*Rates!$C$10 | J32: =SUM(B32:I32) | K32: =J32*1.3 | L32: =K32*1.8
A33: 30 FS | B33: =B23*Rates!$C$23*4.27 | C33: =C23*Rates!$C$22*4.27 | E33: =E23*Rates!$C$9 | F33: =F23*Rates!$C$7 | G33: =G23*Rates!$C$12 | H33: =H23*Rates!$C$6 | I33: =I23*Rates!$C$10 | J33: =SUM(B33:I33) | K33: =J33*1.3 | L33: =K33*1.8
A34: 40 FS | B34: =B24*Rates!$C$23*4.27 | C34: =C24*Rates!$C$22*4.27 | E34: =E24*Rates!$C$9 | F34: =F24*Rates!$C$7 | G34: =G24*Rates!$C$12 | H34: =H24*Rates!$C$6 | I34: =I24*Rates!$C$10 | J34: =SUM(B34:I34) | K34: =J34*1.3 | L34: =K34*1.8
A35: 50 FS | B35: =B25*Rates!$C$23*4.27 | C35: =C25*Rates!$C$22*4.27 | E35: =E25*Rates!$C$9 | F35: =F25*Rates!$C$7 | G35: =G25*Rates!$C$12 | H35: =H25*Rates!$C$6 | I35: =I25*Rates!$C$10 | J35: =SUM(B35:I35) | K35: =J35*1.3 | L35: =K35*1.8
A36: 70 FS | B36: =B26*Rates!$C$23*4.27 | C36: =C26*Rates!$C$22*4.27 | E36: =E26*Rates!$C$9 | F36: =F26*Rates!$C$7 | G36: =G26*Rates!$C$12 | H36: =H26*Rates!$C$6 | I36: =I26*Rates!$C$10 | J36: =SUM(B36:I36) | K36: =J36*1.3 | L36: =K36*1.8
A37: 100 FS | B37: =B27*Rates!$C$23*4.27 | C37: =C27*Rates!$C$22*4.27 | E37: =E27*Rates!$C$9 | F37: =F27*Rates!$C$7 | G37: =G27*Rates!$C$12 | H37: =H27*Rates!$C$6 | I37: =I27*Rates!$C$10 | J37: =SUM(B37:I37) | K37: =J37*1.3 | L37: =K37*1.8

Sheet Gas Burner
A1: BURNER PARTS 50 NM³ (GAIL design Hole Type) | J1: BURNER PARTS 100 NM³ (GAIL design Hole Type) | S1: BURNER PARTS 150 NM³ (GAIL design Hole Type)
A2: S.NO. | B2: PARTICULARS | C2: QTY | D2: UNIT | E2: RATE | F2: AMOUNT | G2: M/C COST | H2: TOTAL AMOUNT | J2: S.NO. | K2: PARTICULARS | L2: QTY | M2: UNIT | N2: RATE | O2: AMOUNT | P2: M/C COST | Q2: TOTAL AMOUNT | S2: 5 | T2: PARTICULARS | U2: QTY | V2: UNIT | W2: RATE | X2: AMOUNT | Y2: M/C COST | Z2: TOTAL AMOUNT
A4: 1 | B4: S.S PIPE | C4: 19 | D4: Kgs | E4: =Rates!C30 | F4: =C4*E4 | H4: =F4+G4 | J4: 1 | K4: S.S PIPE | L4: 34 | M4: Kgs | N4: =E4 | O4: =L4*N4 | Q4: =O4+P4 | S4: 1 | T4: S.S PIPE | U4: 34 | V4: Kgs | W4: =N4 | X4: =U4*W4 | Z4: =X4+Y4
A5: 2 | B5: M.S PLATE | C5: 27 | D5: Kgs | E5: =Rates!C12 | F5: =C5*E5 | H5: =F5+G5 | J5: 2 | K5: M.S PLATE | L5: 42 | M5: Kgs | N5: =E5 | O5: =L5*N5 | Q5: =O5+P5 | S5: 2 | T5: M.S PLATE | U5: 42 | V5: Kgs | W5: =N5 | X5: =U5*W5 | Z5: =X5+Y5
A6: 3 | B6: DRILL | F6: 1800 | H6: =F6+G6 | J6: 3 | K6: DRILL | Q6: 2000 | S6: 3 | T6: DRILL | Z6: 2000
A7: 4 | B7: BUTTERFLY VALVE-6 (INCH ) | C7: 1 | D7: NO | E7: =Rates!K23 | F7: =C7*E7 | H7: =F7+G7 | J7: 4 | K7: BUTTERFLY VALVE-6 (INCH ) | L7: 1 | M7: NO | N7: =E7 | O7: =L7*N7 | Q7: =O7+P7 | S7: 4 | T7: BUTTERFLY VALVE-6 (INCH ) | U7: 1 | V7: NO | W7: =N7 | X7: =U7*W7 | Z7: =X7+Y7
A8: 5 | B8: Ball valve | C8: 1 | D8: NO | E8: =Rates!K26 | F8: =C8*E8 | H8: =F8+G8 | J8: 5 | K8: Ball valve | L8: 1 | M8: NO | N8: =E8 | O8: =L8*N8 | Q8: =O8+P8 | S8: 5 | T8: Ball valve | U8: 1 | V8: NO | W8: =N8 | X8: =U8*W8 | Z8: =X8+Y8
A9: 6 | B9: FLEXIBLE HOSE-40NB*750MM WITH ADOPTER | C9: 1 | D9: NO | E9: =Rates!K27 | F9: =C9*E9 | H9: =F9+G9 | J9: 6 | K9: FLEXIBLE HOSE-40NB*750MM WITH ADOPTER | L9: 1 | M9: NO | N9: =E9 | O9: =L9*N9 | Q9: =O9+P9 | S9: 6 | T9: FLEXIBLE HOSE-40NB*750MM WITH ADOPTER | U9: 1 | V9: NO | W9: =N9 | X9: =U9*W9 | Z9: =X9+Y9
A10: 7 | B10: BURNER PLATE | C10: 40 | D10: Kgs | E10: =Rates!K5 | F10: =C10*E10 | H10: =F10+G10 | J10: 7 | K10: BURNER PLATE | L10: 50 | M10: Kgs | N10: =E10 | O10: =L10*N10 | Q10: =O10+P10 | S10: 7 | T10: BURNER PLATE | U10: 50 | V10: Kgs | W10: =N10 | X10: =U10*W10 | Z10: =X10+Y10
A11: 8 | B11: BURNER BLOCK | C11: 70 | D11: Kgs | E11: =Rates!K25 | F11: =C11*E11 | H11: =F11+G11 | J11: 8 | K11: BURNER BLOCK | L11: 110 | M11: Kgs | N11: =E11 | O11: =L11*N11 | Q11: 4760 | S11: 8 | T11: BURNER BLOCK | U11: 110 | V11: Kgs | W11: =N11 | X11: =U11*W11 | Z11: 4760
A12: 9 | B12: labour charge | F12: 5000 | H12: =F12+G12 | J12: 9 | K12: labour charge | Q12: 5500 | S12: 9 | T12: labour charge | Z12: 5000
A13: 10 | B13: PAINT PRIMER,BOLT | H13: 350 | J13: 10 | K13: PAINT PRIMER,BOLT | Q13: 500 | S13: 10 | T13: PAINT PRIMER,BOLT | Z13: 400
E14: TOTAL | H14: =SUM(H4:H13) | N14: TOTAL | Q14: =SUM(Q4:Q13) | W14: TOTAL | Z14: =SUM(Z4:Z13)
A17: BURNER PARTS 100 NM³ PowerTrade | J17: BURNER PARTS 100 NM³ Ada
A18: S.NO. | B18: PARTICULARS | C18: QTY | D18: UNIT | E18: RATE | F18: AMOUNT | G18: M/C COST | H18: TOTAL AMOUNT | J18: S.NO. | K18: PARTICULARS | L18: QTY | M18: UNIT | N18: RATE | O18: AMOUNT | P18: M/C COST | Q18: TOTAL AMOUNT
A20: 1 | B20: AIR TUBE | C20: 51 | D20: Kgs | E20: 70 | F20: =C20*E20 | G20: 2760 | H20: =F20+G20 | J20: 1 | K20: AIR TUBE | L20: 30 | M20: Kgs | N20: =Rates!K5 | O20: =L20*N20 | P20: 2760 | Q20: =O20+P20
A21: 2 | B21: BAISE | C21: 24 | D21: Kgs | E21: 70 | F21: =C21*E21 | G21: 1500 | H21: =F21+G21 | J21: 2 | K21: BAISE | L21: 22 | M21: Kgs | N21: =N20 | O21: =L21*N21 | P21: 1500 | Q21: =O21+P21
A22: 3 | B22: RING | C22: 8 | D22: Kgs | E22: 70 | F22: =C22*E22 | G22: 750 | H22: =F22+G22 | J22: 3 | K22: RING | L22: 8 | M22: Kgs | N22: =N21 | O22: =L22*N22 | P22: 750 | Q22: =O22+P22
A23: 4 | B23: SS PIPE | C23: 3 | D23: Kgs | E23: 240 | F23: =C23*E23 | H23: =F23+G23 | J23: 4 | K23: SS PIPE | L23: 3 | M23: Kgs | N23: =N4 | O23: =L23*N23 | Q23: =O23+P23
A24: 5 | B24: MS PLATE | C24: 10 | D24: Kgs | E24: 70 | F24: =C24*E24 | G24: 400 | H24: =F24+G24 | J24: 5 | K24: MS PLATE | L24: 10 | M24: Kgs | N24: =N5 | O24: =L24*N24 | P24: 400 | Q24: =O24+P24
A25: 6 | B25: BUTTERFLY VALVE-6 (INCH ) | C25: 1 | D25: NO | E25: 3000 | F25: =C25*E25 | H25: =F25+G25 | J25: 6 | K25: BUTTERFLY VALVE-6 (INCH ) | L25: 1 | M25: NO | N25: =N7 | O25: =L25*N25 | Q25: =O25+P25
A26: 7 | B26: Ball valve | C26: 1 | D26: NO | E26: 2050 | F26: =C26*E26 | H26: =F26+G26 | J26: 7 | K26: Ball valve | L26: 1 | M26: NO | N26: =W8 | O26: =L26*N26 | Q26: =O26+P26
A27: 8 | B27: FLEXIBLE HOSE-40NB*750MM WITH ADOPTER | C27: 1 | D27: NO | E27: 1750 | F27: =C27*E27 | H27: =F27+G27 | J27: 8 | K27: FLEXIBLE HOSE-40NB*750MM WITH ADOPTER | L27: 1 | M27: NO | N27: =W9 | O27: =L27*N27 | Q27: =O27+P27
A28: 9 | B28: BURNER PLATE | C28: 50 | D28: Kgs | E28: 70 | F28: =C28*E28 | H28: =F28+G28 | J28: 9 | K28: BURNER PLATE | L28: 50 | M28: Kgs | N28: =N10 | O28: =L28*N28 | Q28: =O28+P28
A29: 10 | B29: BURNER BLOCK | C29: 110 | D29: Kgs | E29: 41 | F29: =C29*E29 | H29: 4760 | J29: 10 | K29: BURNER BLOCK | L29: 110 | M29: Kgs | N29: =N11 | O29: =L29*N29 | Q29: 4760
A30: 11 | B30: labour charge | H30: 500 | J30: 11 | K30: labour charge | Q30: 500
A31: 12 | B31: PAINT PRIMER,BOLT | H31: 400 | J31: 12 | K31: PAINT PRIMER,BOLT | Q31: 400
E32: TOTAL | H32: =SUM(H20:H31) | N32: TOTAL | Q32: =SUM(Q20:Q31)
B35: Casting weight of ADA – 1 . base – 30 kg
B36: 2 . air tube – 35 kg
B37: 3. Ring – 10 kg
B38: Power trade - 1. Air tube – 60 kg
B39: 2. base - 35 kg
B40: 3. Ring – 10 kg

Sheet Blower
A1: ENCON FUEL COMBUSTORS BLOWERS (DIRECT MOUNTED) (W.E.F Jul'21)
A2: MEDIUM PRESSURE | H2: PERKIN Rates
A3: MODEL | B3: H.P. | C3: CFM | D3: NM3 /HR | E3: PRESSURE | F3: PRICE Without motor | G3: PRICE With motor | H3: Blower weight Approx | I3: Per Kg. Price | J3: Amount | K3: Motor Price ABB | L3: PRICE Without, motor | M3: PRICE With motor | O3: * Raised 12% from Last
A4: ENCON 28/3 | B4: 3 | C4: 300 | D4: 510 | E4: 28” W.G. | F4: 50400 | G4: 69000 | H4: 130 | J4: 28000 | K4: 12500 | L4: =J4*1.8 | M4: =K4*1.5+L4 | O4: 12320 | P4: =J4/H4 | Q4: 45000 | R4: =Q4/(H4*1.8) | S4: =P4/R4-1 | U4: 57000 | V4: =G4/U4-1 | X4: =M4-L4 | Y4: =X4/O4
A5: ENCON 28/5 | B5: 5 | C5: 550 | D5: 930 | E5: 28” W.G. | F5: 51500 | G5: 76000 | H5: 160 | J5: 28622 | K5: 16200 | L5: =J5*1.8 | M5: =K5*1.5+L5 | O5: 16170 | P5: =J5/H5 | Q5: 46000 | R5: =Q5/(H5*1.8) | S5: =P5/R5-1 | U5: 66000 | V5: =G5/U5-1 | X5: =M5-L5 | Y5: =X5/O5
A6: ENCON 28/7.5 | B6: 7.5 | C6: 850 | D6: 1450 | E6: 28” W.G. | F6: 56500 | G6: 95200 | H6: 180 | J6: 31360 | K6: 25800 | L6: =J6*1.8 | M6: =K6*1.5+L6 | O6: 25795 | P6: =J6/H6 | Q6: 50400 | R6: =Q6/(H6*1.8) | S6: =P6/R6-1 | U6: 87000 | V6: =G6/U6-1 | X6: =M6-L6 | Y6: =X6/O6
A7: ENCON 28/10 | B7: 10 | C7: 1200 | D7: 2040 | E7: 28” W.G. | F7: 60500 | G7: 101000 | H7: 190 | J7: 33600 | K7: 27000 | L7: =J7*1.8 | M7: =K7*1.5+L7 | O7: 26950 | P7: =J7/H7 | Q7: 54000 | R7: =Q7/(H7*1.8) | S7: =P7/R7-1 | U7: 92000 | V7: =G7/U7-1 | X7: =M7-L7 | Y7: =X7/O7
A8: ENCON 28/15 | B8: 15 | C8: 1700 | D8: 2890 | E8: 28” W.G. | F8: 76000 | G8: 148000 | H8: 200 | J8: 39200 | K8: 51500 | L8: =J8*1.8 | M8: =K8*1.5+L8 | O8: 51310 | P8: =J8/H8 | Q8: 63000 | R8: =Q8/(H8*1.8) | S8: =P8/R8-1 | U8: 136000 | V8: =G8/U8-1 | X8: =M8-L8 | Y8: =X8/O8
A9: ENCON 28/20 | B9: 20 | C9: 2200 | D9: 3740 | E9: 28” W.G. | F9: 87000 | G9: 168000 | H9: 210 | J9: 44800 | K9: 58000 | L9: =J9*1.8 | M9: =K9*1.5+L9 | O9: 57995 | P9: =J9/H9 | Q9: 72000 | R9: =Q9/(H9*1.8) | S9: =P9/R9-1 | U9: 155000 | V9: =G9/U9-1 | X9: =M9-L9 | Y9: =X9/O9
A10: ENCON 28/25 | B10: 25 | C10: 3000 | D10: 5100 | E10: 28” W.G. | F10: 91000 | G10: 195000 | H10: 220 | J10: 50400 | K10: 69500 | L10: =J10*1.8 | M10: =K10*1.5+L10 | O10: 69230 | P10: =J10/H10 | Q10: 81000 | R10: =Q10/(H10*1.8) | S10: =P10/R10-1 | U10: 180000 | V10: =G10/U10-1 | X10: =M10-L10 | Y10: =X10/O10
A11: ENCON 28/30 | B11: 30 | C11: 3500 | D11: 5950 | E11: 28” W.G. | F11: 111000 | G11: 230000 | H11: 275 | J11: 61600 | K11: 79000 | L11: =J11*1.8 | M11: =K11*1.5+L11 | O11: 78925 | P11: =J11/H11 | Q11: 99000 | R11: =Q11/(H11*1.8) | S11: =P11/R11-1 | U11: 210000 | V11: =G11/U11-1 | X11: =M11-L11 | Y11: =X11/O11
A12: ENCON 28/40 | B12: 40 | C12: 4800 | D12: 7900 | E12: 28” W.G. | F12: 131000 | G12: 296000 | H12: 330 | J12: 72800 | K12: 110000 | L12: =J12*1.8 | M12: =K12*1.5+L12 | O12: 109620 | P12: =J12/H12 | Q12: 117000 | R12: =Q12/(H12*1.8) | S12: =P12/R12-1 | U12: 274000 | V12: =G12/U12-1 | X12: =M12-L12 | Y12: =X12/O12
A13: ENCON 28/50 | B13: 50 | C13: 5950 | D13: 9850 | E13: 28” W.G. | F13: 151500 | G13: 339000 | H13: 370 | J13: 84000 | K13: 125000 | L13: =J13*1.8 | M13: =K13*1.5+L13 | O13: 124215 | P13: =J13/H13 | Q13: 135000 | R13: =Q13/(H13*1.8) | S13: =P13/R13-1 | U13: 318000 | V13: =G13/U13-1 | X13: =M13-L13 | Y13: =X13/O13
A14: ENCON 28/60 | B14: 60 | C14: 7100 | D14: 11750 | E14: 28” W.G. | F14: 175000 | G14: 417000 | H14: 475 | J14: 96320 | K14: 162000 | L14: =J14*1.8 | M14: =K14*1.5+L14 | O14: 161630 | P14: =J14/H14 | Q14: 154800 | R14: =Q14/(H14*1.8) | S14: =P14/R14-1 | U14: 395000 | V14: =G14/U14-1 | X14: =M14-L14 | Y14: =X14/O14
A15: HIGH PRESSURE | H15: PERKIN Rates
A16: MODEL | B16: H.P. | C16: CFM | D16: NM3 /HR | E16: PRESSURE | F16: PRICE Without motor | G16: PRICE With motor | H16: Blower weight Approx | I16: Per Kg. Price | J16: Amount | K16: Motor Price ABB | L16: PRICE Without, motor | M16: PRICE With motor | O16: * Raised 12% from Last
A17: ENCON 40/5 | B17: 5 | C17: 400 | D17: 680 | E17: 40” W.G. | F17: 56500 | G17: 81000 | H17: 160 | J17: 31360 | K17: 16200 | L17: =J17*1.8 | M17: =K17*1.5+L17 | P17: =J17/H17 | Q17: 50400 | R17: =Q17/(H17*1.8) | S17: =P17/R17-1 | U17: 74000 | V17: =G17/U17-1
A18: ENCON 40/7.5 | B18: 7.5 | C18: 600 | D18: 1020 | E18: 40” W.G. | F18: 60500 | G18: 99500 | H18: 180 | J18: 33600 | K18: 25800 | L18: =J18*1.8 | M18: =K18*1.5+L18 | P18: =J18/H18 | Q18: 54000 | R18: =Q18/(H18*1.8) | S18: =P18/R18-1 | U18: 91000 | V18: =G18/U18-1
A19: ENCON 40/10 | B19: 10 | C19: 800 | D19: 1360 | E19: 40” W.G. | F19: 76000 | G19: 111000 | H19: 190 | J19: 39200 | K19: 27000 | L19: =J19*1.8 | M19: =K19*1.5+L19 | P19: =J19/H19 | Q19: 63000 | R19: =Q19/(H19*1.8) | S19: =P19/R19-1 | U19: 101000 | V19: =G19/U19-1
A20: ENCON 40/15 | B20: 15 | C20: 1200 | D20: 2040 | E20: 40” W.G. | F20: 87000 | G20: 158000 | H20: 200 | J20: 44800 | K20: 51500 | L20: =J20*1.8 | M20: =K20*1.5+L20 | P20: =J20/H20 | Q20: 72000 | R20: =Q20/(H20*1.8) | S20: =P20/R20-1 | U20: 145000 | V20: =G20/U20-1
A21: ENCON 40/20 | B21: 20 | C21: 1600 | D21: 2730 | E21: 40” W.G. | F21: 91000 | G21: 178000 | H21: 210 | J21: 50400 | K21: 58000 | L21: =J21*1.8 | M21: =K21*1.5+L21 | P21: =J21/H21 | Q21: 81000 | R21: =Q21/(H21*1.8) | S21: =P21/R21-1 | U21: 164000 | V21: =G21/U21-1
A22: ENCON 40/25 | B22: 25 | C22: 2000 | D22: 3400 | E22: 40” W.G. | F22: 111000 | G22: 215000 | H22: 220 | J22: 61600 | K22: 69500 | L22: =J22*1.8 | M22: =K22*1.5+L22 | P22: =J22/H22 | Q22: 99000 | R22: =Q22/(H22*1.8) | S22: =P22/R22-1 | U22: 198000 | V22: =G22/U22-1
A23: ENCON 40/30 | B23: 30 | C23: 2400 | D23: 4000 | E23: 40” W.G. | F23: 131000 | G23: 250000 | H23: 275 | J23: 72800 | K23: 79000 | L23: =J23*1.8 | M23: =K23*1.5+L23 | P23: =J23/H23 | Q23: 117000 | R23: =Q23/(H23*1.8) | S23: =P23/R23-1 | U23: 228000 | V23: =G23/U23-1
A24: ENCON 40/40 | B24: 40 | C24: 3200 | D24: 5200 | E24: 40” W.G. | F24: 151500 | G24: 316500 | H24: 330 | J24: 84000 | K24: 110000 | L24: =J24*1.8 | M24: =K24*1.5+L24 | P24: =J24/H24 | Q24: 135000 | R24: =Q24/(H24*1.8) | S24: =P24/R24-1 | U24: 292000 | V24: =G24/U24-1
A25: ENCON 40/50 | B25: 50 | C25: 4000 | D25: 6500 | E25: 40” W.G. | F25: 175000 | G25: 361000 | H25: 370 | J25: 96320 | K25: 125000 | L25: =J25*1.8 | M25: =K25*1.5+L25 | P25: =J25/H25 | Q25: 155000 | R25: =Q25/(H25*1.8) | S25: =P25/R25-1 | U25: 334000 | V25: =G25/U25-1
A26: ENCON 40/60 | B26: 60 | C26: 4800 | D26: 7800 | E26: 40” W.G. | F26: 198000 | G26: 441000 | H26: 475 | J26: 109760 | K26: 162000 | L26: =J26*1.8 | M26: =K26*1.5+L26 | P26: =J26/H26 | Q26: 177000 | R26: =Q26/(H26*1.8) | S26: =P26/R26-1 | U26: 417000 | V26: =G26/U26-1
A27: Note:
A28: (1) The ex works price indicated for fuel combustors are inclusive of the electric motor of reputed make, such as, NGEF, ABB, Crompton etc. on which the impeller would be directly mounted.
A29: (2) Quoted prices for 40 HP and above Blowers are for V Belt/coupled mounting.
A37: Blower DM 40 | L37: Blower DM 28
A38: Model | B38: M.S Angle 65,50 KG | C38: M.S Sheet 8mm Kg | D38: M.S Sheet 4mm KG | E38: M.S Sheet 2mm KG | F38: MS Flat KG | G38: CI Hub Nos | H38: Hardware KG | I38: Total Cost | L38: Model | M38: M.S Angle 65,50 Kg | N38: M.S Sheet 5mm Kg | O38: M.S Sheet 4mm Kg | P38: M.S Sheet 2mm Kg | Q38: MS Flat Kg | R38: CI Hub Nos | S38: Hardware Kg | T38: Total Cost
A39: 5/40 | B39: 14 | C39: 34 | D39: 50 | E39: 15 | F39: 6 | G39: 1 | H39: 3 | I39: =K49 | L39: 5/28 | M39: 12 | N39: 32 | O39: 51 | P39: 11 | Q39: 3 | R39: 1 | S39: 3 | T39: =V49
A40: 7.5/40 | B40: 14 | C40: 39 | D40: 61 | E40: 15 | F40: 8 | G40: 1 | H40: 3 | I40: =K50 | L40: 7.5/28 | M40: 13 | N40: 34 | O40: 48 | P40: 13 | Q40: 3 | R40: 1 | S40: 3 | T40: =V50
A41: 10/40 | B41: 14 | C41: 40 | D41: 62 | E41: 15 | F41: 8 | G41: 1 | H41: 3 | I41: =K51 | L41: 10/28 | M41: 13 | N41: 39 | O41: 50 | P41: 15 | Q41: 3 | R41: 1 | S41: 3 | T41: =V51
A42: 15/40 | B42: 25 | C42: 43 | D42: 62 | E42: 19 | F42: 8 | G42: 1 | H42: 3 | I42: =K52 | L42: 15/28 | M42: 24 | N42: 47 | O42: 61 | P42: 15 | Q42: 4 | R42: 1 | S42: 3 | T42: =V52
A43: 20/40 | B43: 30 | C43: 46 | D43: 63 | E43: 20 | F43: 9 | G43: 1 | H43: 3 | I43: =K53 | L43: 20/28 | M43: 25 | N43: 49 | O43: 62 | P43: 15 | Q43: 4 | R43: 1 | S43: 3 | T43: =V53
A44: 25/40 | B44: 30 | C44: 46 | D44: 63 | E44: 20 | F44: 9 | G44: 1 | H44: 3 | I44: =K54 | L44: 25/28 | M44: 25 | N44: 50 | O44: 65 | P44: 17 | Q44: 4 | R44: 1 | S44: 3 | T44: =V54
A45: 30/40 | B45: 30 | C45: 48 | D45: 65 | E45: 21 | F45: 8 | G45: 1 | H45: 3 | I45: =K55 | L45: 30/28 | M45: 25 | N45: 50 | O45: 66 | P45: 17 | Q45: 4 | R45: 1 | S45: 3 | T45: =V55
A48: Model | B48: M.S Angle 65,50 KG | C48: M.S Sheet 5mm* 8mm Kg | D48: M.S Sheet 4mm* 3mm KG | E48: M.S Sheet 2mm KG | F48: MS Flat KG | G48: CI Hub Nos | H48: Hardware KG | J48: 0.3 | K48: 0.8 | L48: Model | M48: M.S Angle 65,50 Kg | N48: M.S Sheet 5mm* 8mm Kg | O48: M.S Sheet 4mm* 3mm Kg | P48: M.S Sheet 2.5mm* 2mm Kg | Q48: MS Flat Kg | R48: CI Hub Nos | S48: Hardware Kg | U48: 0.3 | V48: 0.8
A49: 5/40 | B49: =B39*Rates!$C$9 | C49: =C39*Rates!$C$21 | D49: =D39*Rates!$C$19 | E49: =E39*Rates!$C$17 | F49: =F39*Rates!$C$11 | G49: =G39*Rates!$C$4 | H49: =H39*Rates!$C$6 | I49: =SUM(B49:H49) | J49: =I49*1.3 | K49: =J49*1.8 | L49: 5/28 | M49: =M39*Rates!$C$9 | N49: =N39*Rates!$C$14 | O49: =O39*Rates!$C$19 | P49: =P39*Rates!$C$17 | Q49: =Q39*Rates!$C$11 | R49: =R39*Rates!$C$4 | S49: =S39*Rates!$C$6 | T49: =SUM(M49:S49) | U49: =T49*1.3 | V49: =U49*1.8
...

Sheet HPU
A1: Costing of Heating & Pumping Unit 3 KW Date : 01.07.2022 | Q1: Costing of Heating & Pumping Unit 6 KW Date : 01.07.2022 | AG1: Costing of Heating & Pumping Unit 9 KW Date : 01.07.2022 | AW1: Costing of Heating & Pumping Unit 12 KW Date : 01.07.2022 | BM1: Costing of Heating & Pumping Unit 16 KW Date : 01.07.2022 | CC1: Costing of Heating & Pumping Unit 20 KW Date : 01.07.2022 | CS1: Costing of Heating & Pumping Unit 24 KW Date : 01.07.2022 | DH1: Costing of Heating & Pumping Unit 30 KW Date : 01.07.2022 | DX1: Costing of Heating & Pumping Unit 36 KW Date : 01.07.2022 | EN1: Costing of Heating & Pumping Unit 48 KW Date : 01.07.2022
A2: Duplex 1 | G2: Duplex 2 | K2: Simplex | Q2: Duplex 1 | W2: Duplex 2 | AA2: Simplex | AG2: Duplex 1 | AM2: Duplex 2 | AQ2: Simplex | AW2: Duplex 1 | BC2: Duplex 2 | BG2: Simplex | BM2: Duplex 1 | BS2: Duplex 2 | BW2: Simplex | CC2: Duplex 1 | CI2: Duplex 2 | CM2: Simplex | CS2: Duplex 1 | CY2: Duplex 2 | DC2: Simplex | DH2: Duplex 1 | DN2: Duplex 2 | DR2: Simplex | DX2: Duplex 1 | ED2: Duplex 2 | EH2: Simplex | EN2: Duplex 1 | ET2: Duplex 2 | EX2: Simplex
A3: S No. | B3: Items | C3: Qty. | D3: Unit | E3: Rate | F3: Amount | Q3: S No. | R3: Items | S3: Qty. | T3: Unit | U3: Rate | V3: Amount | AG3: S No. | AH3: Items | AI3: Qty. | AJ3: Unit | AK3: Rate | AL3: Amount | AW3: S No. | AX3: Items | AY3: Qty. | AZ3: Unit | BA3: Rate | BB3: Amount | BM3: S No. | BN3: Items | BO3: Qty. | BP3: Unit | BQ3: Rate | BR3: Amount | CC3: S No. | CD3: Items | CE3: Qty. | CF3: Unit | CG3: Rate | CH3: Amount | CS3: S No. | CT3: Items | CU3: Qty. | CV3: Unit | CW3: Rate | CX3: Amount | DH3: S No. | DI3: Items | DJ3: Qty. | DK3: Unit | DL3: Rate | DM3: Amount | DX3: S No. | DY3: Items | DZ3: Qty. | EA3: Unit | EB3: Rate | EC3: Amount | EN3: S No. | EO3: Items | EP3: Qty. | EQ3: Unit | ER3: Rate | ES3: Amount
G4: Qty. | H4: Unit | I4: Rate | J4: Amount | K4: Qty. | L4: Unit | M4: Rate | N4: Amount | O4: Pre. Price | W4: Qty. | X4: Unit | Y4: Rate | Z4: Amount | AA4: Qty. | AB4: Unit | AC4: Rate | AD4: Amount | AE4: Pre. Price | AM4: Qty. | AN4: Unit | AO4: Rate | AP4: Amount | AQ4: Qty. | AR4: Unit | AS4: Rate | AT4: Amount | AU4: Pre. Price | BC4: Qty. | BD4: Unit | BE4: Rate | BF4: Amount | BG4: Qty. | BH4: Unit | BI4: Rate | BJ4: Amount | BK4: Pre. Price | BS4: Qty. | BT4: Unit | BU4: Rate | BV4: Amount | BW4: Qty. | BX4: Unit | BY4: Rate | BZ4: Amount | CA4: Pre. Price | CI4: Qty. | CJ4: Unit | CK4: Rate | CL4: Amount | CM4: Qty. | CN4: Unit | CO4: Rate | CP4: Amount | CQ4: Pre.Price | CY4: Qty. | CZ4: Unit | DA4: Rate | DB4: Amount | DC4: Qty. | DD4: Unit | DE4: Rate | DF4: Amount | DN4: Qty. | DO4: Unit | DP4: Rate | DQ4: Amount | DR4: Qty. | DS4: Unit | DT4: Rate | DU4: Amount | DV4: Pre. Price | ED4: Qty. | EE4: Unit | EF4: Rate | EG4: Amount | EH4: Qty. | EI4: Unit | EJ4: Rate | EK4: Amount | EL4: Pre Price | ET4: Qty. | EU4: Unit | EV4: Rate | EW4: Amount | EX4: Qty. | EY4: Unit | EZ4: Rate | FA4: Amount | FB4: Pre. Price
A5: 1 | B5: M.S Channel 75x40(2700 mm long) | C5: 20 | D5: Kg | E5: =Rates!C10 | F5: =C5*E5 | G5: 25.9 | H5: kg | I5: =E5 | J5: =G5*I5 | K5: 20 | L5: Kg | M5: =I5 | N5: =K5*M5 | O5: 71 | Q5: 1 | R5: M.S Channel 75x40(2700 mm long) | S5: 20 | T5: Kg | U5: =Rates!C10 | V5: =S5*U5 | W5: 25.9 | X5: kg | Y5: =U5 | Z5: =W5*Y5 | AA5: 20 | AB5: Kg | AC5: =U5 | AD5: =AA5*AC5 | AE5: 71 | AG5: 1 | AH5: M.S Channel 75x40(2900 mm long) | AI5: 21.4 | AJ5: Kg | AK5: =Rates!C10 | AL5: =AI5*AK5 | AM5: 42.8 | AN5: kg | AO5: =AK5 | AP5: =AM5*AO5 | AQ5: 21.4 | AR5: Kg | AS5: =AK5 | AT5: =AQ5*AS5 | AU5: 71 | AW5: 1 | AX5: M.S Channel 75x40(3200 mm long) | AY5: 22.8 | AZ5: Kg | BA5: =Rates!C10 | BB5: =AY5*BA5 | BC5: 45.6 | BD5: kg | BE5: =BA5 | BF5: =BC5*BE5 | BG5: 22.8 | BH5: Kg | BI5: =BA5 | BJ5: =BG5*BI5 | BK5: 71 | BM5: 1 | BN5: M.S Channel 75x40(3200 mm long) | BO5: 22.8 | BP5: Kg | BQ5: =Rates!C10 | BR5: =BO5*BQ5 | BS5: 45.6 | BT5: kg | BU5: =BQ5 | BV5: =BS5*BU5 | BW5: 22.8 | BX5: Kg | BY5: =BQ5 | BZ5: =BW5*BY5 | CA5: 71 | CC5: 1 | CD5: M.S Channel 75x40(3400 mm long) | CE5: 25 | CF5: Kg | CG5: =Rates!C10 | CH5: =CE5*CG5 | CI5: 48 | CJ5: kg | CK5: =CG5 | CL5: =CI5*CK5 | CM5: 25 | CN5: Kg | CO5: =CG5 | CP5: =CM5*CO5 | CQ5: 71 | CS5: 1 | CT5: M.S Channel 75x40(3600 mm long) | CU5: 25.7 | CV5: Kg | CW5: =Rates!C10 | CX5: =CU5*CW5 | CY5: 51.4 | CZ5: kg | DA5: =CW5 | DB5: =CY5*DA5 | DC5: 25.7 | DD5: Kg | DE5: =CW5 | DF5: =DC5*DE5 | DG5: =DF5-CP5 | DH5: 1 | DI5: M.S Channel 75x40(3600 mm long) | DJ5: 25.7 | DK5: Kg | DL5: =Rates!C10 | DM5: =DJ5*DL5 | DN5: 51.4 | DO5: kg | DP5: =DL5 | DQ5: =DN5*DP5 | DR5: 25.7 | DS5: Kg | DT5: =DL5 | DU5: =DR5*DT5 | DV5: 71 | DX5: 1 | DY5: M.S Channel 75x40(3600 mm long) | DZ5: 25.7 | EA5: Kg | EB5: =Rates!C10 | EC5: =DZ5*EB5 | ED5: 51.4 | EE5: kg | EF5: =EB5 | EG5: =ED5*EF5 | EH5: 25.7 | EI5: Kg | EJ5: =EB5 | EK5: =EH5*EJ5 | EL5: 71 | EN5: 1 | EO5: M.S Channel 100x50( 5 mtr. long) | EP5: 47.8 | EQ5: Kg | ER5: =Rates!C10 | ES5: =EP5*ER5 | ET5: 68.8 | EU5: kg | EV5: =ER5 | EW5: =ET5*EV5 | EX5: 47.8 | EY5: Kg | EZ5: =ER5 | FA5: =EX5*EZ5 | FB5: 71
A6: 2 | B6: M.S pipe 150 NB X 700 MM long | C6: 19.7 | D6: Kg | E6: =Rates!C22 | F6: =C6*E6 | G6: 39.4 | H6: kg | I6: =E6 | J6: =G6*I6 | K6: 19.7 | L6: Kg | M6: =I6 | N6: =K6*M6 | O6: 135 | Q6: 2 | R6: M.S pipe 200 NB X 700 MM long | S6: 29 | T6: Kg | U6: =Rates!C22 | V6: =S6*U6 | W6: 58 | X6: kg | Y6: =U6 | Z6: =W6*Y6 | AA6: 29 | AB6: Kg | AC6: =U6 | AD6: =AA6*AC6 | AE6: 135 | AG6: 2 | AH6: M.S Plate 5 mmx1051x700 mm | AI6: 29 | AJ6: Kg | AK6: =Rates!C14 | AL6: =AI6*AK6 | AM6: 58 | AN6: kg | AO6: =AK6 | AP6: =AM6*AO6 | AQ6: 29 | AR6: Kg | AS6: =AK6 | AT6: =AQ6*AS6 | AU6: 72 | AW6: 2 | AX6: M.S Plate 5 mmx1051x700 mm | AY6: 29 | AZ6: Kg | BA6: =Rates!C20 | BB6: =AY6*BA6 | BC6: 58 | BD6: kg | BE6: =BA6 | BF6: =BC6*BE6 | BG6: 29 | BH6: Kg | BI6: =BA6 | BJ6: =BG6*BI6 | BK6: 72 | BM6: 2 | BN6: M.S Plate 5 mmx1318x700 mm | BO6: 36 | BP6: Kg | BQ6: =Rates!C20 | BR6: =BO6*BQ6 | BS6: 72 | BT6: kg | BU6: =BQ6 | BV6: =BS6*BU6 | BW6: 36 | BX6: Kg | BY6: =BQ6 | BZ6: =BW6*BY6 | CA6: 72 | CC6: 2 | CD6: M.S Plate 5 mmx 1428x700 mm | CE6: 39 | CF6: Kg | CG6: =Rates!C20 | CH6: =CE6*CG6 | CI6: 78 | CJ6: kg | CK6: =CG6 | CL6: =CI6*CK6 | CM6: 39 | CN6: Kg | CO6: =CG6 | CP6: =CM6*CO6 | CQ6: 72 | CS6: 2 | CT6: M.S Plate 5 mmx 1444x700 mm | CU6: 39.6 | CV6: Kg | CW6: =Rates!C20 | CX6: =CU6*CW6 | CY6: 79 | CZ6: kg | DA6: =CW6 | DB6: =CY6*DA6 | DC6: 39.6 | DD6: Kg | DE6: =CW6 | DF6: =DC6*DE6 | DG6: =DF6-CP6 | DH6: 2 | DI6: M.S Plate 5 mmx 2166x700 mm | DJ6: 59.5 | DK6: Kg | DL6: =Rates!C20 | DM6: =DJ6*DL6 | DN6: 119 | DO6: kg | DP6: =DL6 | DQ6: =DN6*DP6 | DR6: 59.5 | DS6: Kg | DT6: =DL6 | DU6: =DR6*DT6 | DV6: 72 | DX6: 2 | DY6: M.S Plate 5 mmx 2245x700 mm | DZ6: 61.6 | EA6: Kg | EB6: =Rates!C20 | EC6: =DZ6*EB6 | ED6: 123 | EE6: kg | EF6: =EB6 | EG6: =ED6*EF6 | EH6: 61.6 | EI6: Kg | EJ6: =EB6 | EK6: =EH6*EJ6 | EL6: 72 | EN6: 2 | EO6: M.S Plate 5 mmx 2794x700 mm | EP6: 77 | EQ6: Kg | ER6: =Rates!C20 | ES6: =EP6*ER6 | ET6: 154 | EU6: kg | EV6: =ER6 | EW6: =ET6*EV6 | EX6: 77 | EY6: Kg | EZ6: =ER6 | FA6: =EX6*EZ6 | FB6: 72
A7: 3 | B7: HR Sheet 850x1000X3 MM | C7: 20 | D7: Kg | E7: =Rates!C18 | F7: =C7*E7 | G7: 28 | H7: kg | I7: =E7 | J7: =G7*I7 | K7: 20 | L7: Kg | M7: =I7 | N7: =K7*M7 | O7: 77 | Q7: 3 | R7: HR Sheet 1050X900X3 MM | S7: 22.3 | T7: Kg | U7: =Rates!C18 | V7: =S7*U7 | W7: 30.7 | X7: kg | Y7: =U7 | Z7: =W7*Y7 | AA7: 22.3 | AB7: Kg | AC7: =U7 | AD7: =AA7*AC7 | AE7: 77 | AG7: 3 | AH7: HR Sheet 1100x1000X3 MM | AI7: 25.9 | AJ7: Kg | AK7: =Rates!C18 | AL7: =AI7*AK7 | AM7: 35.3 | AN7: kg | AO7: =AK7 | AP7: =AM7*AO7 | AQ7: 25.9 | AR7: Kg | AS7: =AK7 | AT7: =AQ7*AS7 | AU7: 77 | AW7: 3 | AX7: HR Sheet 1100x1200X3 MM | AY7: 31 | AZ7: Kg | BA7: =Rates!C18 | BB7: =AY7*BA7 | BC7: 41 | BD7: kg | BE7: =BA7 | BF7: =BC7*BE7 | BG7: 31 | BH7: Kg | BI7: =BA7 | BJ7: =BG7*BI7 | BK7: 77 | BM7: 3 | BN7: HR Sheet 1100x1200X3 MM | BO7: 31 | BP7: Kg | BQ7: =Rates!C18 | BR7: =BO7*BQ7 | BS7: 41 | BT7: kg | BU7: =BQ7 | BV7: =BS7*BU7 | BW7: 31 | BX7: Kg | BY7: =BQ7 | BZ7: =BW7*BY7 | CA7: 77 | CC7: 3 | CD7: HR Sheet 1200x1300X3 MM | CE7: 36.7 | CF7: Kg | CG7: =Rates!C18 | CH7: =CE7*CG7 | CI7: 50.8 | CJ7: kg | CK7: =CG7 | CL7: =CI7*CK7 | CM7: 36.7 | CN7: Kg | CO7: =CG7 | CP7: =CM7*CO7 | CQ7: 77 | CS7: 3 | CT7: HR Sheet 1300x1400X3 MM | CU7: 42.8 | CV7: Kg | CW7: =Rates!C18 | CX7: =CU7*CW7 | CY7: 90.4 | CZ7: kg | DA7: =CW7 | DB7: =CY7*DA7 | DC7: 42.8 | DD7: Kg | DE7: =CW7 | DF7: =DC7*DE7 | DG7: =DF7-CP7 | DH7: 3 | DI7: HR Sheet 1300x1400X3 MM | DJ7: 42.8 | DK7: Kg | DL7: =Rates!C18 | DM7: =DJ7*DL7 | DN7: 90.4 | DO7: kg | DP7: =DL7 | DQ7: =DN7*DP7 | DR7: 42.8 | DS7: Kg | DT7: =DL7 | DU7: =DR7*DT7 | DV7: 77 | DX7: 3 | DY7: HR Sheet 1300x1400X3 MM | DZ7: 42.8 | EA7: Kg | EB7: =Rates!C18 | EC7: =DZ7*EB7 | ED7: 90.4 | EE7: kg | EF7: =EB7 | EG7: =ED7*EF7 | EH7: 42.8 | EI7: Kg | EJ7: =EB7 | EK7: =EH7*EJ7 | EL7: 77 | EN7: 3 | EO7: HR Sheet 1800x1900X5 MM | EP7: 134 | EQ7: Kg | ER7: =Rates!C14 | ES7: =EP7*ER7 | ET7: 183 | EU7: kg | EV7: =ER7 | EW7: =ET7*EV7 | EX7: 134 | EY7: Kg | EZ7: =ER7 | FA7: =EX7*EZ7 | FB7: 72
A8: 4 | B8: HR Sheet 709 X175X3 MM | C8: 3 | D8: Kg | E8: =E7 | F8: =C8*E8 | G8: 6 | H8: kg | I8: =E8 | J8: =G8*I8 | K8: 3 | L8: Kg | M8: =I8 | N8: =K8*M8 | O8: 77 | Q8: 4 | R8: HR Sheet 286 diaX175X3 MM | S8: 6 | T8: Kg | U8: =U7 | V8: =S8*U8 | W8: 12 | X8: kg | Y8: =U8 | Z8: =W8*Y8 | AA8: 6 | AB8: Kg | AC8: =U8 | AD8: =AA8*AC8 | AE8: 77 | AG8: 4 | AH8: HR Sheet 1274 X175X3 MM | AI8: 5 | AJ8: Kg | AK8: =AK7 | AL8: =AI8*AK8 | AM8: 10 | AN8: kg | AO8: =AK8 | AP8: =AM8*AO8 | AQ8: 5 | AR8: Kg | AS8: =AK8 | AT8: =AQ8*AS8 | AU8: 77 | AW8: 4 | AX8: HR Sheet 1274 X175X3 MM | AY8: 5 | AZ8: Kg | BA8: =Rates!C18 | BB8: =AY8*BA8 | BC8: 10 | BD8: kg | BE8: =BA8 | BF8: =BC8*BE8 | BG8: 5 | BH8: Kg | BI8: =BA8 | BJ8: =BG8*BI8 | BK8: 77 | BM8: 4 | BN8: HR Sheet 1318 X175X3 MM | BO8: 5.4 | BP8: Kg | BQ8: =Rates!C18 | BR8: =BO8*BQ8 | BS8: 10.8 | BT8: kg | BU8: =BQ8 | BV8: =BS8*BU8 | BW8: 5.4 | BX8: Kg | BY8: =BQ8 | BZ8: =BW8*BY8 | CA8: 77 | CC8: 4 | CD8: HR Sheet 1632 X175X3 MM | CE8: 7 | CF8: Kg | CG8: =Rates!C18 | CH8: =CE8*CG8 | CI8: 14 | CJ8: kg | CK8: =CG8 | CL8: =CI8*CK8 | CM8: 7 | CN8: Kg | CO8: =CG8 | CP8: =CM8*CO8 | CQ8: 77 | CS8: 4 | CT8: HR Sheet 1651 X175X3 MM | CU8: 7 | CV8: Kg | CW8: =Rates!C18 | CX8: =CU8*CW8 | CY8: 14 | CZ8: kg | DA8: =CW8 | DB8: =CY8*DA8 | DC8: 7 | DD8: Kg | DE8: =CW8 | DF8: =DC8*DE8 | DG8: =DF8-CP8 | DH8: 4 | DI8: HR Sheet 2373 X175X3 MM | DJ8: 10 | DK8: Kg | DL8: =Rates!C18 | DM8: =DJ8*DL8 | DN8: 20 | DO8: kg | DP8: =DL8 | DQ8: =DN8*DP8 | DR8: 10 | DS8: Kg | DT8: =DL8 | DU8: =DR8*DT8 | DV8: 77 | DX8: 4 | DY8: HR Sheet 2452 X175X3 MM | DZ8: 10 | EA8: Kg | EB8: =Rates!C18 | EC8: =DZ8*EB8 | ED8: 20 | EE8: kg | EF8: =EB8 | EG8: =ED8*EF8 | EH8: 10 | EI8: Kg | EJ8: =EB8 | EK8: =EH8*EJ8 | EL8: 77 | EN8: 4 | EO8: HR Sheet 3000 X175X3 MM | EP8: 12 | EQ8: Kg | ER8: =Rates!C18 | ES8: =EP8*ER8 | ET8: 24 | EU8: kg | EV8: =ER8 | EW8: =ET8*EV8 | EX8: 12 | EY8: Kg | EZ8: =ER8 | FA8: =EX8*EZ8 | FB8: 77
A9: 5 | B9: M.S Plate 226 diax3 mm | C9: 1.5 | D9: Kg | E9: =E8 | F9: =C9*E9 | G9: 3 | H9: Kg | I9: =E9 | J9: =G9*I9 | K9: 1.5 | L9: Kg | M9: =I9 | N9: =K9*M9 | O9: 77 | Q9: 5 | R9: M.S Plate 5 MM motor base | S9: 10.8 | T9: Kg | U9: =Rates!C20 | V9: =S9*U9 | W9: 10.8 | X9: kg | Y9: =U9 | Z9: =W9*Y9 | AA9: 10.8 | AB9: Kg | AC9: =U9 | AD9: =AA9*AC9 | AE9: 72 | AG9: 5 | AH9: M.S Plate 406 diax3 mm | AI9: 3.8 | AJ9: Kg | AK9: =AK8 | AL9: =AI9*AK9 | AM9: 7.6 | AN9: Kg | AO9: =AK9 | AP9: =AM9*AO9 | AQ9: 3.8 | AR9: Kg | AS9: =AK9 | AT9: =AQ9*AS9 | AU9: 77 | AW9: 5 | AX9: M.S Plate 406 diax3 mm | AY9: 3.8 | AZ9: Kg | BA9: =Rates!C18 | BB9: =AY9*BA9 | BC9: 7.6 | BD9: Kg | BE9: =BA9 | BF9: =BC9*BE9 | BG9: 3.8 | BH9: Kg | BI9: =BA9 | BJ9: =BG9*BI9 | BK9: 77 | BM9: 5 | BN9: M.S Plate 486 diax3 mm | BO9: 5.5 | BP9: Kg | BQ9: =Rates!C18 | BR9: =BO9*BQ9 | BS9: 11 | BT9: Kg | BU9: =BQ9 | BV9: =BS9*BU9 | BW9: 5.5 | BX9: Kg | BY9: =BQ9 | BZ9: =BW9*BY9 | CA9: 77 | CC9: 5 | CD9: M.S Plate 526 diax3 mm | CE9: 6.5 | CF9: Kg | CG9: =Rates!C18 | CH9: =CE9*CG9 | CI9: 13 | CJ9: Kg | CK9: =CG9 | CL9: =CI9*CK9 | CM9: 6.5 | CN9: Kg | CO9: =CG9 | CP9: =CM9*CO9 | CQ9: 77 | CS9: 5 | CT9: M.S Plate 526 diax3 mm | CU9: 6.5 | CV9: Kg | CW9: =Rates!C18 | CX9: =CU9*CW9 | CY9: 13 | CZ9: Kg | DA9: =CW9 | DB9: =CY9*DA9 | DC9: 6.5 | DD9: Kg | DE9: =CW9 | DF9: =DC9*DE9 | DG9: =DF9-CP9 | DH9: 5 | DI9: M.S Plate 756 diax3 mm | DJ9: 13.4 | DK9: Kg | DL9: =Rates!C18 | DM9: =DJ9*DL9 | DN9: 26.8 | DO9: Kg | DP9: =DL9 | DQ9: =DN9*DP9 | DR9: 13.4 | DS9: Kg | DT9: =DL9 | DU9: =DR9*DT9 | DV9: 77 | DX9: 5 | DY9: M.S Plate 781 diax3 mm | DZ9: 14 | EA9: Kg | EB9: =Rates!C18 | EC9: =DZ9*EB9 | ED9: 28 | EE9: Kg | EF9: =EB9 | EG9: =ED9*EF9 | EH9: 14 | EI9: Kg | EJ9: =EB9 | EK9: =EH9*EJ9 | EL9: 77 | EN9: 5 | EO9: M.S Plate 956 diax3 mm | EP9: 21 | EQ9: Kg | ER9: =Rates!C18 | ES9: =EP9*ER9 | ET9: 42 | EU9: Kg | EV9: =ER9 | EW9: =ET9*EV9 | EX9: 21 | EY9: Kg | EZ9: =ER9 | FA9: =EX9*EZ9 | FB9: 77
A10: 6 | B10: M.S Plate 5 MM motor base | C10: 10.8 | D10: Kg | E10: =Rates!C20 | F10: =C10*E10 | G10: 10.8 | H10: kg | I10: =E10 | J10: =G10*I10 | K10: 10.8 | L10: Kg | M10: =I10 | N10: =K10*M10 | O10: 72 | Q10: 6 | R10: M.S Plate 280 diax16 MM | S10: 9.8 | T10: Kg | U10: =Rates!C12 | V10: =S10*U10 | W10: 19.6 | X10: Kg | Y10: =U10 | Z10: =W10*Y10 | AA10: 9.8 | AB10: Kg | AC10: =U10 | AD10: =AA10*AC10 | AE10: 72 | AG10: 6 | AH10: M.S Plate 5 MM motor base | AI10: 10.8 | AJ10: Kg | AK10: =AK6 | AL10: =AI10*AK10 | AM10: 10.8 | AN10: kg | AO10: =AK10 | AP10: =AM10*AO10 | AQ10: 10.8 | AR10: Kg | AS10: =AK10 | AT10: =AQ10*AS10 | AU10: 72 | AW10: 6 | AX10: M.S Plate 5 MM motor base | AY10: 10.8 | AZ10: Kg | BA10: =Rates!C20 | BB10: =AY10*BA10 | BC10: 10.8 | BD10: kg | BE10: =BA10 | BF10: =BC10*BE10 | BG10: 10.8 | BH10: Kg | BI10: =BA10 | BJ10: =BG10*BI10 | BK10: 72 | BM10: 6 | BN10: M.S Plate 5 MM motor base | BO10: 10.8 | BP10: Kg | BQ10: =Rates!C20 | BR10: =BO10*BQ10 | BS10: 10.8 | BT10: kg | BU10: =BQ10 | BV10: =BS10*BU10 | BW10: 10.8 | BX10: Kg | BY10: =BQ10 | BZ10: =BW10*BY10 | CA10: 72 | CC10: 6 | CD10: M.S Plate 5 MM motor base | CE10: 10.8 | CF10: Kg | CG10: =Rates!C20 | CH10: =CE10*CG10 | CI10: 10.8 | CJ10: kg | CK10: =CG10 | CL10: =CI10*CK10 | CM10: 10.8 | CN10: Kg | CO10: =CG10 | CP10: =CM10*CO10 | CQ10: 72 | CS10: 6 | CT10: M.S Plate 5 MM motor base | CU10: 10.8 | CV10: Kg | CW10: =Rates!C20 | CX10: =CU10*CW10 | CY10: 10.8 | CZ10: kg | DA10: =CW10 | DB10: =CY10*DA10 | DC10: 10.8 | DD10: Kg | DE10: =CW10 | DF10: =DC10*DE10 | DG10: =DF10-CP10 | DH10: 6 | DI10: M.S Plate 5 MM motor base | DJ10: 14 | DK10: Kg | DL10: =Rates!C14 | DM10: =DJ10*DL10 | DN10: 14 | DO10: kg | DP10: =DL10 | DQ10: =DN10*DP10 | DR10: 14 | DS10: Kg | DT10: =DL10 | DU10: =DR10*DT10 | DV10: 72 | DX10: 6 | DY10: M.S Plate 5 MM motor base | DZ10: 14 | EA10: Kg | EB10: =Rates!C14 | EC10: =DZ10*EB10 | ED10: 14 | EE10: kg | EF10: =EB10 | EG10: =ED10*EF10 | EH10: 14 | EI10: Kg | EJ10: =EB10 | EK10: =EH10*EJ10 | EL10: 72 | EN10: 6 | EO10: M.S Plate 5 MM motor base | EP10: 14 | EQ10: Kg | ER10: =Rates!C20 | ES10: =EP10*ER10 | ET10: 14 | EU10: kg | EV10: =ER10 | EW10: =ET10*EV10 | EX10: 14 | EY10: Kg | EZ10: =ER10 | FA10: =EX10*EZ10 | FB10: 72
A11: 7 | B11: M.S Plate 220 diax16 MM | C11: 6 | D11: Kg | E11: =Rates!C13 | F11: =C11*E11 | G11: 12 | H11: Kg | I11: =E11 | J11: =G11*I11 | K11: 6 | L11: Kg | M11: =I11 | N11: =K11*M11 | O11: 72 | Q11: 7 | R11: M.S Plate 240 dia x5 mm | S11: 2.2 | T11: Kg | U11: =Rates!C14 | V11: =S11*U11 | W11: 4.4 | X11: Kg | Y11: =U11 | Z11: =W11*Y11 | AA11: 2.2 | AB11: Kg | AC11: =U11 | AD11: =AA11*AC11 | AE11: 72 | AG11: 7 | AH11: M.S Plate 400 diax16 MM | AI11: 20 | AJ11: Kg | AK11: =Rates!C12 | AL11: =AI11*AK11 | AM11: 40 | AN11: Kg | AO11: =AK11 | AP11: =AM11*AO11 | AQ11: 20 | AR11: Kg | AS11: =AK11 | AT11: =AQ11*AS11 | AU11: 72 | AW11: 7 | AX11: M.S Plate 400 diax16 MM | AY11: 20 | AZ11: Kg | BA11: =Rates!C12 | BB11: =AY11*BA11 | BC11: 40 | BD11: Kg | BE11: =BA11 | BF11: =BC11*BE11 | BG11: 20 | BH11: Kg | BI11: =BA11 | BJ11: =BG11*BI11 | BK11: 72 | BM11: 7 | BN11: M.S Plate 480 diax16 MM | BO11: 29 | BP11: Kg | BQ11: =Rates!C12 | BR11: =BO11*BQ11 | BS11: 58 | BT11: Kg | BU11: =BQ11 | BV11: =BS11*BU11 | BW11: 29 | BX11: Kg | BY11: =BQ11 | BZ11: =BW11*BY11 | CA11: 72 | CC11: 7 | CD11: M.S Plate 520 diax16 MM | CE11: 34 | CF11: Kg | CG11: =Rates!C12 | CH11: =CE11*CG11 | CI11: 68 | CJ11: Kg | CK11: =CG11 | CL11: =CI11*CK11 | CM11: 34 | CN11: Kg | CO11: =CG11 | CP11: =CM11*CO11 | CQ11: 72 | CS11: 7 | CT11: M.S Plate 520 diax16 MM | CU11: 34 | CV11: Kg | CW11: =Rates!C12 | CX11: =CU11*CW11 | CY11: 68 | CZ11: Kg | DA11: =CW11 | DB11: =CY11*DA11 | DC11: 34 | DD11: Kg | DE11: =CW11 | DF11: =DC11*DE11 | DG11: =DF11-CP11 | DH11: 7 | DI11: M.S Plate 750 diax16 MM | DJ11: 70 | DK11: Kg | DL11: =Rates!C12 | DM11: =DJ11*DL11 | DN11: 140 | DO11: Kg | DP11: =DL11 | DQ11: =DN11*DP11 | DR11: 70 | DS11: Kg | DT11: =DL11 | DU11: =DR11*DT11 | DV11: 72 | DX11: 7 | DY11: M.S Plate 775 diax16 MM | DZ11: 75.4 | EA11: Kg | EB11: =Rates!C12 | EC11: =DZ11*EB11 | ED11: 150.8 | EE11: Kg | EF11: =EB11 | EG11: =ED11*EF11 | EH11: 75.4 | EI11: Kg | EJ11: =EB11 | EK11: =EH11*EJ11 | EL11: 72 | EN11: 7 | EO11: M.S Plate 950 diax20MM | EP11: 141 | EQ11: Kg | ER11: =Rates!C12 | ES11: =EP11*ER11 | ET11: 282 | EU11: Kg | EV11: =ER11 | EW11: =ET11*EV11 | EX11: 141 | EY11: Kg | EZ11: =ER11 | FA11: =EX11*EZ11 | FB11: 72
